<<< -- process set (n=8) with 6 CPU-bound process
<<< -- seed=768; lambda=0.001000; bound=1024

CPU-bound process A0: arrival time 54ms; 29 CPU bursts:
==> CPU burst 3764ms ==> I/O burst 686ms
==> CPU burst 1732ms ==> I/O burst 212ms
==> CPU burst 844ms ==> I/O burst 493ms
==> CPU burst 168ms ==> I/O burst 372ms
==> CPU burst 736ms ==> I/O burst 141ms
==> CPU burst 1372ms ==> I/O burst 554ms
==> CPU burst 1808ms ==> I/O burst 149ms
==> CPU burst 1808ms ==> I/O burst 266ms
==> CPU burst 848ms ==> I/O burst 75ms
==> CPU burst 3384ms ==> I/O burst 17ms
==> CPU burst 104ms ==> I/O burst 428ms
==> CPU burst 3924ms ==> I/O burst 667ms
==> CPU burst 3388ms ==> I/O burst 94ms
==> CPU burst 100ms ==> I/O burst 487ms
==> CPU burst 3868ms ==> I/O burst 112ms
==> CPU burst 1516ms ==> I/O burst 311ms
==> CPU burst 1260ms ==> I/O burst 413ms
==> CPU burst 728ms ==> I/O burst 773ms
==> CPU burst 2568ms ==> I/O burst 348ms
==> CPU burst 1220ms ==> I/O burst 883ms
==> CPU burst 2296ms ==> I/O burst 664ms
==> CPU burst 3268ms ==> I/O burst 923ms
==> CPU burst 3468ms ==> I/O burst 288ms
==> CPU burst 2392ms ==> I/O burst 108ms
==> CPU burst 1976ms ==> I/O burst 564ms
==> CPU burst 312ms ==> I/O burst 545ms
==> CPU burst 1440ms ==> I/O burst 136ms
==> CPU burst 3052ms ==> I/O burst 558ms
==> CPU burst 2044ms

CPU-bound process A1: arrival time 56ms; 31 CPU bursts:
==> CPU burst 2828ms ==> I/O burst 322ms
==> CPU burst 1444ms ==> I/O burst 167ms
==> CPU burst 2476ms ==> I/O burst 417ms
==> CPU burst 2256ms ==> I/O burst 290ms
==> CPU burst 1188ms ==> I/O burst 777ms
==> CPU burst 2812ms ==> I/O burst 863ms
==> CPU burst 368ms ==> I/O burst 173ms
==> CPU burst 200ms ==> I/O burst 607ms
==> CPU burst 1044ms ==> I/O burst 592ms
==> CPU burst 940ms ==> I/O burst 445ms
==> CPU burst 660ms ==> I/O burst 28ms
==> CPU burst 2196ms ==> I/O burst 976ms
==> CPU burst 36ms ==> I/O burst 637ms
==> CPU burst 4060ms ==> I/O burst 90ms
==> CPU burst 3904ms ==> I/O burst 534ms
==> CPU burst 1488ms ==> I/O burst 404ms
==> CPU burst 1080ms ==> I/O burst 51ms
==> CPU burst 916ms ==> I/O burst 71ms
==> CPU burst 3724ms ==> I/O burst 111ms
==> CPU burst 1764ms ==> I/O burst 282ms
==> CPU burst 860ms ==> I/O burst 99ms
==> CPU burst 2700ms ==> I/O burst 767ms
==> CPU burst 100ms ==> I/O burst 586ms
==> CPU burst 420ms ==> I/O burst 709ms
==> CPU burst 3504ms ==> I/O burst 671ms
==> CPU burst 3504ms ==> I/O burst 334ms
==> CPU burst 2352ms ==> I/O burst 251ms
==> CPU burst 2652ms ==> I/O burst 768ms
==> CPU burst 3812ms ==> I/O burst 527ms
==> CPU burst 2288ms ==> I/O burst 166ms
==> CPU burst 388ms

CPU-bound process A2: arrival time 456ms; 9 CPU bursts:
==> CPU burst 1896ms ==> I/O burst 618ms
==> CPU burst 2940ms ==> I/O burst 439ms
==> CPU burst 248ms ==> I/O burst 464ms
==> CPU burst 952ms ==> I/O burst 774ms
==> CPU burst 1796ms ==> I/O burst 411ms
==> CPU burst 2200ms ==> I/O burst 15ms
==> CPU burst 1512ms ==> I/O burst 787ms
==> CPU burst 1764ms ==> I/O burst 84ms
==> CPU burst 1768ms

CPU-bound process A3: arrival time 758ms; 16 CPU bursts:
==> CPU burst 548ms ==> I/O burst 799ms
==> CPU burst 428ms ==> I/O burst 938ms
==> CPU burst 1432ms ==> I/O burst 317ms
==> CPU burst 3896ms ==> I/O burst 124ms
==> CPU burst 804ms ==> I/O burst 65ms
==> CPU burst 2564ms ==> I/O burst 380ms
==> CPU burst 3416ms ==> I/O burst 889ms
==> CPU burst 3756ms ==> I/O burst 651ms
==> CPU burst 3864ms ==> I/O burst 423ms
==> CPU burst 1144ms ==> I/O burst 150ms
==> CPU burst 492ms ==> I/O burst 368ms
==> CPU burst 2704ms ==> I/O burst 176ms
==> CPU burst 316ms ==> I/O burst 668ms
==> CPU burst 204ms ==> I/O burst 332ms
==> CPU burst 2328ms ==> I/O burst 896ms
==> CPU burst 2760ms

CPU-bound process A4: arrival time 346ms; 2 CPU bursts:
==> CPU burst 2428ms ==> I/O burst 509ms
==> CPU burst 2532ms

CPU-bound process A5: arrival time 115ms; 1 CPU bursts:
==> CPU burst 564ms

I/O-bound process A6: arrival time 242ms; 27 CPU bursts:
==> CPU burst 761ms ==> I/O burst 2264ms
==> CPU burst 903ms ==> I/O burst 2048ms
==> CPU burst 303ms ==> I/O burst 7328ms
==> CPU burst 194ms ==> I/O burst 6896ms
==> CPU burst 203ms ==> I/O burst 2800ms
==> CPU burst 603ms ==> I/O burst 3064ms
==> CPU burst 95ms ==> I/O burst 1056ms
==> CPU burst 556ms ==> I/O burst 3376ms
==> CPU burst 599ms ==> I/O burst 560ms
==> CPU burst 58ms ==> I/O burst 2056ms
==> CPU burst 455ms ==> I/O burst 3112ms
==> CPU burst 826ms ==> I/O burst 2640ms
==> CPU burst 587ms ==> I/O burst 1920ms
==> CPU burst 292ms ==> I/O burst 4480ms
==> CPU burst 572ms ==> I/O burst 520ms
==> CPU burst 494ms ==> I/O burst 7088ms
==> CPU burst 19ms ==> I/O burst 4216ms
==> CPU burst 355ms ==> I/O burst 2968ms
==> CPU burst 81ms ==> I/O burst 7440ms
==> CPU burst 25ms ==> I/O burst 944ms
==> CPU burst 445ms ==> I/O burst 3208ms
==> CPU burst 35ms ==> I/O burst 3040ms
==> CPU burst 245ms ==> I/O burst 7240ms
==> CPU burst 732ms ==> I/O burst 2064ms
==> CPU burst 850ms ==> I/O burst 6800ms
==> CPU burst 667ms ==> I/O burst 248ms
==> CPU burst 370ms

I/O-bound process A7: arrival time 357ms; 21 CPU bursts:
==> CPU burst 297ms ==> I/O burst 7864ms
==> CPU burst 598ms ==> I/O burst 2456ms
==> CPU burst 721ms ==> I/O burst 2736ms
==> CPU burst 641ms ==> I/O burst 1944ms
==> CPU burst 128ms ==> I/O burst 6168ms
==> CPU burst 277ms ==> I/O burst 848ms
==> CPU burst 984ms ==> I/O burst 5208ms
==> CPU burst 961ms ==> I/O burst 3432ms
==> CPU burst 587ms ==> I/O burst 792ms
==> CPU burst 33ms ==> I/O burst 2584ms
==> CPU burst 875ms ==> I/O burst 2352ms
==> CPU burst 53ms ==> I/O burst 240ms
==> CPU burst 64ms ==> I/O burst 3496ms
==> CPU burst 264ms ==> I/O burst 1048ms
==> CPU burst 228ms ==> I/O burst 2264ms
==> CPU burst 37ms ==> I/O burst 5496ms
==> CPU burst 364ms ==> I/O burst 4312ms
==> CPU burst 278ms ==> I/O burst 2512ms
==> CPU burst 23ms ==> I/O burst 7880ms
==> CPU burst 188ms ==> I/O burst 3896ms
==> CPU burst 214ms

<<< PROJECT SIMULATIONS
<<< -- t_cs=6ms; alpha=0.95; t_slice=128ms
time 0ms: Simulator started for FCFS [Q empty]
time 54ms: Process A0 arrived; added to ready queue [Q A0]
time 56ms: Process A1 arrived; added to ready queue [Q A1]
time 57ms: Process A0 started using the CPU for 3764ms burst [Q A1]
time 115ms: Process A5 arrived; added to ready queue [Q A1 A5]
time 242ms: Process A6 arrived; added to ready queue [Q A1 A5 A6]
time 346ms: Process A4 arrived; added to ready queue [Q A1 A5 A6 A4]
time 357ms: Process A7 arrived; added to ready queue [Q A1 A5 A6 A4 A7]
time 456ms: Process A2 arrived; added to ready queue [Q A1 A5 A6 A4 A7 A2]
time 758ms: Process A3 arrived; added to ready queue [Q A1 A5 A6 A4 A7 A2 A3]
time 3821ms: Process A0 completed a CPU burst; 28 bursts to go [Q A1 A5 A6 A4 A7 A2 A3]
time 3821ms: Process A0 switching out of CPU; blocking on I/O until time 4510ms [Q A1 A5 A6 A4 A7 A2 A3]
time 3827ms: Process A1 started using the CPU for 2828ms burst [Q A5 A6 A4 A7 A2 A3]
time 4510ms: Process A0 completed I/O; added to ready queue [Q A5 A6 A4 A7 A2 A3 A0]
time 6655ms: Process A1 completed a CPU burst; 30 bursts to go [Q A5 A6 A4 A7 A2 A3 A0]
time 6655ms: Process A1 switching out of CPU; blocking on I/O until time 6980ms [Q A5 A6 A4 A7 A2 A3 A0]
time 6661ms: Process A5 started using the CPU for 564ms burst [Q A6 A4 A7 A2 A3 A0]
time 6980ms: Process A1 completed I/O; added to ready queue [Q A6 A4 A7 A2 A3 A0 A1]
time 7225ms: Process A5 terminated [Q A6 A4 A7 A2 A3 A0 A1]
time 7231ms: Process A6 started using the CPU for 761ms burst [Q A4 A7 A2 A3 A0 A1]
time 7992ms: Process A6 completed a CPU burst; 26 bursts to go [Q A4 A7 A2 A3 A0 A1]
time 7992ms: Process A6 switching out of CPU; blocking on I/O until time 10259ms [Q A4 A7 A2 A3 A0 A1]
time 7998ms: Process A4 started using the CPU for 2428ms burst [Q A7 A2 A3 A0 A1]
time 10259ms: Process A6 completed I/O; added to ready queue [Q A7 A2 A3 A0 A1 A6]
time 10426ms: Process A4 completed a CPU burst; 1 burst to go [Q A7 A2 A3 A0 A1 A6]
time 10426ms: Process A4 switching out of CPU; blocking on I/O until time 10938ms [Q A7 A2 A3 A0 A1 A6]
time 10432ms: Process A7 started using the CPU for 297ms burst [Q A2 A3 A0 A1 A6]
time 10729ms: Process A7 completed a CPU burst; 20 bursts to go [Q A2 A3 A0 A1 A6]
time 10729ms: Process A7 switching out of CPU; blocking on I/O until time 18596ms [Q A2 A3 A0 A1 A6]
time 10735ms: Process A2 started using the CPU for 1896ms burst [Q A3 A0 A1 A6]
time 10938ms: Process A4 completed I/O; added to ready queue [Q A3 A0 A1 A6 A4]
time 12631ms: Process A2 completed a CPU burst; 8 bursts to go [Q A3 A0 A1 A6 A4]
time 12631ms: Process A2 switching out of CPU; blocking on I/O until time 13252ms [Q A3 A0 A1 A6 A4]
time 12637ms: Process A3 started using the CPU for 548ms burst [Q A0 A1 A6 A4]
time 13185ms: Process A3 completed a CPU burst; 15 bursts to go [Q A0 A1 A6 A4]
time 13185ms: Process A3 switching out of CPU; blocking on I/O until time 13987ms [Q A0 A1 A6 A4]
time 13191ms: Process A0 started using the CPU for 1732ms burst [Q A1 A6 A4]
time 13252ms: Process A2 completed I/O; added to ready queue [Q A1 A6 A4 A2]
time 13987ms: Process A3 completed I/O; added to ready queue [Q A1 A6 A4 A2 A3]
time 14923ms: Process A0 completed a CPU burst; 27 bursts to go [Q A1 A6 A4 A2 A3]
time 14923ms: Process A0 switching out of CPU; blocking on I/O until time 15138ms [Q A1 A6 A4 A2 A3]
time 14929ms: Process A1 started using the CPU for 1444ms burst [Q A6 A4 A2 A3]
time 15138ms: Process A0 completed I/O; added to ready queue [Q A6 A4 A2 A3 A0]
time 16373ms: Process A1 completed a CPU burst; 29 bursts to go [Q A6 A4 A2 A3 A0]
time 16373ms: Process A1 switching out of CPU; blocking on I/O until time 16543ms [Q A6 A4 A2 A3 A0]
time 16379ms: Process A6 started using the CPU for 903ms burst [Q A4 A2 A3 A0]
time 16543ms: Process A1 completed I/O; added to ready queue [Q A4 A2 A3 A0 A1]
time 17282ms: Process A6 completed a CPU burst; 25 bursts to go [Q A4 A2 A3 A0 A1]
time 17282ms: Process A6 switching out of CPU; blocking on I/O until time 19333ms [Q A4 A2 A3 A0 A1]
time 17288ms: Process A4 started using the CPU for 2532ms burst [Q A2 A3 A0 A1]
time 18596ms: Process A7 completed I/O; added to ready queue [Q A2 A3 A0 A1 A7]
time 19333ms: Process A6 completed I/O; added to ready queue [Q A2 A3 A0 A1 A7 A6]
time 19820ms: Process A4 terminated [Q A2 A3 A0 A1 A7 A6]
time 19826ms: Process A2 started using the CPU for 2940ms burst [Q A3 A0 A1 A7 A6]
time 22766ms: Process A2 completed a CPU burst; 7 bursts to go [Q A3 A0 A1 A7 A6]
time 22766ms: Process A2 switching out of CPU; blocking on I/O until time 23208ms [Q A3 A0 A1 A7 A6]
time 22772ms: Process A3 started using the CPU for 428ms burst [Q A0 A1 A7 A6]
time 23200ms: Process A3 completed a CPU burst; 14 bursts to go [Q A0 A1 A7 A6]
time 23200ms: Process A3 switching out of CPU; blocking on I/O until time 24141ms [Q A0 A1 A7 A6]
time 23206ms: Process A0 started using the CPU for 844ms burst [Q A1 A7 A6]
time 23208ms: Process A2 completed I/O; added to ready queue [Q A1 A7 A6 A2]
time 24050ms: Process A0 completed a CPU burst; 26 bursts to go [Q A1 A7 A6 A2]
time 24050ms: Process A0 switching out of CPU; blocking on I/O until time 24546ms [Q A1 A7 A6 A2]
time 24056ms: Process A1 started using the CPU for 2476ms burst [Q A7 A6 A2]
time 24141ms: Process A3 completed I/O; added to ready queue [Q A7 A6 A2 A3]
time 24546ms: Process A0 completed I/O; added to ready queue [Q A7 A6 A2 A3 A0]
time 26532ms: Process A1 completed a CPU burst; 28 bursts to go [Q A7 A6 A2 A3 A0]
time 26532ms: Process A1 switching out of CPU; blocking on I/O until time 26952ms [Q A7 A6 A2 A3 A0]
time 26538ms: Process A7 started using the CPU for 598ms burst [Q A6 A2 A3 A0]
time 26952ms: Process A1 completed I/O; added to ready queue [Q A6 A2 A3 A0 A1]
time 27136ms: Process A7 completed a CPU burst; 19 bursts to go [Q A6 A2 A3 A0 A1]
time 27136ms: Process A7 switching out of CPU; blocking on I/O until time 29595ms [Q A6 A2 A3 A0 A1]
time 27142ms: Process A6 started using the CPU for 303ms burst [Q A2 A3 A0 A1]
time 27445ms: Process A6 completed a CPU burst; 24 bursts to go [Q A2 A3 A0 A1]
time 27445ms: Process A6 switching out of CPU; blocking on I/O until time 34776ms [Q A2 A3 A0 A1]
time 27451ms: Process A2 started using the CPU for 248ms burst [Q A3 A0 A1]
time 27699ms: Process A2 completed a CPU burst; 6 bursts to go [Q A3 A0 A1]
time 27699ms: Process A2 switching out of CPU; blocking on I/O until time 28166ms [Q A3 A0 A1]
time 27705ms: Process A3 started using the CPU for 1432ms burst [Q A0 A1]
time 28166ms: Process A2 completed I/O; added to ready queue [Q A0 A1 A2]
time 29137ms: Process A3 completed a CPU burst; 13 bursts to go [Q A0 A1 A2]
time 29137ms: Process A3 switching out of CPU; blocking on I/O until time 29457ms [Q A0 A1 A2]
time 29143ms: Process A0 started using the CPU for 168ms burst [Q A1 A2]
time 29311ms: Process A0 completed a CPU burst; 25 bursts to go [Q A1 A2]
time 29311ms: Process A0 switching out of CPU; blocking on I/O until time 29686ms [Q A1 A2]
time 29317ms: Process A1 started using the CPU for 2256ms burst [Q A2]
time 29457ms: Process A3 completed I/O; added to ready queue [Q A2 A3]
time 29595ms: Process A7 completed I/O; added to ready queue [Q A2 A3 A7]
time 29686ms: Process A0 completed I/O; added to ready queue [Q A2 A3 A7 A0]
time 31573ms: Process A1 completed a CPU burst; 27 bursts to go [Q A2 A3 A7 A0]
time 31573ms: Process A1 switching out of CPU; blocking on I/O until time 31866ms [Q A2 A3 A7 A0]
time 31579ms: Process A2 started using the CPU for 952ms burst [Q A3 A7 A0]
time 31866ms: Process A1 completed I/O; added to ready queue [Q A3 A7 A0 A1]
time 32531ms: Process A2 completed a CPU burst; 5 bursts to go [Q A3 A7 A0 A1]
time 32531ms: Process A2 switching out of CPU; blocking on I/O until time 33308ms [Q A3 A7 A0 A1]
time 32537ms: Process A3 started using the CPU for 3896ms burst [Q A7 A0 A1]
time 33308ms: Process A2 completed I/O; added to ready queue [Q A7 A0 A1 A2]
time 34776ms: Process A6 completed I/O; added to ready queue [Q A7 A0 A1 A2 A6]
time 36433ms: Process A3 completed a CPU burst; 12 bursts to go [Q A7 A0 A1 A2 A6]
time 36433ms: Process A3 switching out of CPU; blocking on I/O until time 36560ms [Q A7 A0 A1 A2 A6]
time 36439ms: Process A7 started using the CPU for 721ms burst [Q A0 A1 A2 A6]
time 36560ms: Process A3 completed I/O; added to ready queue [Q A0 A1 A2 A6 A3]
time 37160ms: Process A7 completed a CPU burst; 18 bursts to go [Q A0 A1 A2 A6 A3]
time 37160ms: Process A7 switching out of CPU; blocking on I/O until time 39899ms [Q A0 A1 A2 A6 A3]
time 37166ms: Process A0 started using the CPU for 736ms burst [Q A1 A2 A6 A3]
time 37902ms: Process A0 completed a CPU burst; 24 bursts to go [Q A1 A2 A6 A3]
time 37902ms: Process A0 switching out of CPU; blocking on I/O until time 38046ms [Q A1 A2 A6 A3]
time 37908ms: Process A1 started using the CPU for 1188ms burst [Q A2 A6 A3]
time 38046ms: Process A0 completed I/O; added to ready queue [Q A2 A6 A3 A0]
time 39096ms: Process A1 completed a CPU burst; 26 bursts to go [Q A2 A6 A3 A0]
time 39096ms: Process A1 switching out of CPU; blocking on I/O until time 39876ms [Q A2 A6 A3 A0]
time 39102ms: Process A2 started using the CPU for 1796ms burst [Q A6 A3 A0]
time 39876ms: Process A1 completed I/O; added to ready queue [Q A6 A3 A0 A1]
time 39899ms: Process A7 completed I/O; added to ready queue [Q A6 A3 A0 A1 A7]
time 40898ms: Process A2 completed a CPU burst; 4 bursts to go [Q A6 A3 A0 A1 A7]
time 40898ms: Process A2 switching out of CPU; blocking on I/O until time 41312ms [Q A6 A3 A0 A1 A7]
time 40904ms: Process A6 started using the CPU for 194ms burst [Q A3 A0 A1 A7]
time 41098ms: Process A6 completed a CPU burst; 23 bursts to go [Q A3 A0 A1 A7]
time 41098ms: Process A6 switching out of CPU; blocking on I/O until time 47997ms [Q A3 A0 A1 A7]
time 41104ms: Process A3 started using the CPU for 804ms burst [Q A0 A1 A7]
time 41312ms: Process A2 completed I/O; added to ready queue [Q A0 A1 A7 A2]
time 41908ms: Process A3 completed a CPU burst; 11 bursts to go [Q A0 A1 A7 A2]
time 41908ms: Process A3 switching out of CPU; blocking on I/O until time 41976ms [Q A0 A1 A7 A2]
time 41914ms: Process A0 started using the CPU for 1372ms burst [Q A1 A7 A2]
time 41976ms: Process A3 completed I/O; added to ready queue [Q A1 A7 A2 A3]
time 43286ms: Process A0 completed a CPU burst; 23 bursts to go [Q A1 A7 A2 A3]
time 43286ms: Process A0 switching out of CPU; blocking on I/O until time 43843ms [Q A1 A7 A2 A3]
time 43292ms: Process A1 started using the CPU for 2812ms burst [Q A7 A2 A3]
time 43843ms: Process A0 completed I/O; added to ready queue [Q A7 A2 A3 A0]
time 46104ms: Process A1 completed a CPU burst; 25 bursts to go [Q A7 A2 A3 A0]
time 46104ms: Process A1 switching out of CPU; blocking on I/O until time 46970ms [Q A7 A2 A3 A0]
time 46110ms: Process A7 started using the CPU for 641ms burst [Q A2 A3 A0]
time 46751ms: Process A7 completed a CPU burst; 17 bursts to go [Q A2 A3 A0]
time 46751ms: Process A7 switching out of CPU; blocking on I/O until time 48698ms [Q A2 A3 A0]
time 46757ms: Process A2 started using the CPU for 2200ms burst [Q A3 A0]
time 46970ms: Process A1 completed I/O; added to ready queue [Q A3 A0 A1]
time 47997ms: Process A6 completed I/O; added to ready queue [Q A3 A0 A1 A6]
time 48698ms: Process A7 completed I/O; added to ready queue [Q A3 A0 A1 A6 A7]
time 48957ms: Process A2 completed a CPU burst; 3 bursts to go [Q A3 A0 A1 A6 A7]
time 48957ms: Process A2 switching out of CPU; blocking on I/O until time 48975ms [Q A3 A0 A1 A6 A7]
time 48963ms: Process A3 started using the CPU for 2564ms burst [Q A0 A1 A6 A7]
time 48975ms: Process A2 completed I/O; added to ready queue [Q A0 A1 A6 A7 A2]
time 51527ms: Process A3 completed a CPU burst; 10 bursts to go [Q A0 A1 A6 A7 A2]
time 51527ms: Process A3 switching out of CPU; blocking on I/O until time 51910ms [Q A0 A1 A6 A7 A2]
time 51533ms: Process A0 started using the CPU for 1808ms burst [Q A1 A6 A7 A2]
time 51910ms: Process A3 completed I/O; added to ready queue [Q A1 A6 A7 A2 A3]
time 53341ms: Process A0 completed a CPU burst; 22 bursts to go [Q A1 A6 A7 A2 A3]
time 53341ms: Process A0 switching out of CPU; blocking on I/O until time 53493ms [Q A1 A6 A7 A2 A3]
time 53347ms: Process A1 started using the CPU for 368ms burst [Q A6 A7 A2 A3]
time 53493ms: Process A0 completed I/O; added to ready queue [Q A6 A7 A2 A3 A0]
time 53715ms: Process A1 completed a CPU burst; 24 bursts to go [Q A6 A7 A2 A3 A0]
time 53715ms: Process A1 switching out of CPU; blocking on I/O until time 53891ms [Q A6 A7 A2 A3 A0]
time 53721ms: Process A6 started using the CPU for 203ms burst [Q A7 A2 A3 A0]
time 53891ms: Process A1 completed I/O; added to ready queue [Q A7 A2 A3 A0 A1]
time 53924ms: Process A6 completed a CPU burst; 22 bursts to go [Q A7 A2 A3 A0 A1]
time 53924ms: Process A6 switching out of CPU; blocking on I/O until time 56727ms [Q A7 A2 A3 A0 A1]
time 53930ms: Process A7 started using the CPU for 128ms burst [Q A2 A3 A0 A1]
time 54058ms: Process A7 completed a CPU burst; 16 bursts to go [Q A2 A3 A0 A1]
time 54058ms: Process A7 switching out of CPU; blocking on I/O until time 60229ms [Q A2 A3 A0 A1]
time 54064ms: Process A2 started using the CPU for 1512ms burst [Q A3 A0 A1]
time 55576ms: Process A2 completed a CPU burst; 2 bursts to go [Q A3 A0 A1]
time 55576ms: Process A2 switching out of CPU; blocking on I/O until time 56366ms [Q A3 A0 A1]
time 55582ms: Process A3 started using the CPU for 3416ms burst [Q A0 A1]
time 56366ms: Process A2 completed I/O; added to ready queue [Q A0 A1 A2]
time 56727ms: Process A6 completed I/O; added to ready queue [Q A0 A1 A2 A6]
time 58998ms: Process A3 completed a CPU burst; 9 bursts to go [Q A0 A1 A2 A6]
time 58998ms: Process A3 switching out of CPU; blocking on I/O until time 59890ms [Q A0 A1 A2 A6]
time 59004ms: Process A0 started using the CPU for 1808ms burst [Q A1 A2 A6]
time 59890ms: Process A3 completed I/O; added to ready queue [Q A1 A2 A6 A3]
time 60229ms: Process A7 completed I/O; added to ready queue [Q A1 A2 A6 A3 A7]
time 60812ms: Process A0 completed a CPU burst; 21 bursts to go [Q A1 A2 A6 A3 A7]
time 60812ms: Process A0 switching out of CPU; blocking on I/O until time 61081ms [Q A1 A2 A6 A3 A7]
time 60818ms: Process A1 started using the CPU for 200ms burst [Q A2 A6 A3 A7]
time 61018ms: Process A1 completed a CPU burst; 23 bursts to go [Q A2 A6 A3 A7]
time 61018ms: Process A1 switching out of CPU; blocking on I/O until time 61628ms [Q A2 A6 A3 A7]
time 61024ms: Process A2 started using the CPU for 1764ms burst [Q A6 A3 A7]
time 61081ms: Process A0 completed I/O; added to ready queue [Q A6 A3 A7 A0]
time 61628ms: Process A1 completed I/O; added to ready queue [Q A6 A3 A7 A0 A1]
time 62788ms: Process A2 completed a CPU burst; 1 burst to go [Q A6 A3 A7 A0 A1]
time 62788ms: Process A2 switching out of CPU; blocking on I/O until time 62875ms [Q A6 A3 A7 A0 A1]
time 62794ms: Process A6 started using the CPU for 603ms burst [Q A3 A7 A0 A1]
time 62875ms: Process A2 completed I/O; added to ready queue [Q A3 A7 A0 A1 A2]
time 63397ms: Process A6 completed a CPU burst; 21 bursts to go [Q A3 A7 A0 A1 A2]
time 63397ms: Process A6 switching out of CPU; blocking on I/O until time 66464ms [Q A3 A7 A0 A1 A2]
time 63403ms: Process A3 started using the CPU for 3756ms burst [Q A7 A0 A1 A2]
time 66464ms: Process A6 completed I/O; added to ready queue [Q A7 A0 A1 A2 A6]
time 67159ms: Process A3 completed a CPU burst; 8 bursts to go [Q A7 A0 A1 A2 A6]
time 67159ms: Process A3 switching out of CPU; blocking on I/O until time 67813ms [Q A7 A0 A1 A2 A6]
time 67165ms: Process A7 started using the CPU for 277ms burst [Q A0 A1 A2 A6]
time 67442ms: Process A7 completed a CPU burst; 15 bursts to go [Q A0 A1 A2 A6]
time 67442ms: Process A7 switching out of CPU; blocking on I/O until time 68293ms [Q A0 A1 A2 A6]
time 67448ms: Process A0 started using the CPU for 848ms burst [Q A1 A2 A6]
time 67813ms: Process A3 completed I/O; added to ready queue [Q A1 A2 A6 A3]
time 68293ms: Process A7 completed I/O; added to ready queue [Q A1 A2 A6 A3 A7]
time 68296ms: Process A0 completed a CPU burst; 20 bursts to go [Q A1 A2 A6 A3 A7]
time 68296ms: Process A0 switching out of CPU; blocking on I/O until time 68374ms [Q A1 A2 A6 A3 A7]
time 68302ms: Process A1 started using the CPU for 1044ms burst [Q A2 A6 A3 A7]
time 68374ms: Process A0 completed I/O; added to ready queue [Q A2 A6 A3 A7 A0]
time 69346ms: Process A1 completed a CPU burst; 22 bursts to go [Q A2 A6 A3 A7 A0]
time 69346ms: Process A1 switching out of CPU; blocking on I/O until time 69941ms [Q A2 A6 A3 A7 A0]
time 69352ms: Process A2 started using the CPU for 1768ms burst [Q A6 A3 A7 A0]
time 69941ms: Process A1 completed I/O; added to ready queue [Q A6 A3 A7 A0 A1]
time 71120ms: Process A2 terminated [Q A6 A3 A7 A0 A1]
time 71126ms: Process A6 started using the CPU for 95ms burst [Q A3 A7 A0 A1]
time 71221ms: Process A6 completed a CPU burst; 20 bursts to go [Q A3 A7 A0 A1]
time 71221ms: Process A6 switching out of CPU; blocking on I/O until time 72280ms [Q A3 A7 A0 A1]
time 71227ms: Process A3 started using the CPU for 3864ms burst [Q A7 A0 A1]
time 72280ms: Process A6 completed I/O; added to ready queue [Q A7 A0 A1 A6]
time 75091ms: Process A3 completed a CPU burst; 7 bursts to go [Q A7 A0 A1 A6]
time 75091ms: Process A3 switching out of CPU; blocking on I/O until time 75517ms [Q A7 A0 A1 A6]
time 75097ms: Process A7 started using the CPU for 984ms burst [Q A0 A1 A6]
time 75517ms: Process A3 completed I/O; added to ready queue [Q A0 A1 A6 A3]
time 76081ms: Process A7 completed a CPU burst; 14 bursts to go [Q A0 A1 A6 A3]
time 76081ms: Process A7 switching out of CPU; blocking on I/O until time 81292ms [Q A0 A1 A6 A3]
time 76087ms: Process A0 started using the CPU for 3384ms burst [Q A1 A6 A3]
time 79471ms: Process A0 completed a CPU burst; 19 bursts to go [Q A1 A6 A3]
time 79471ms: Process A0 switching out of CPU; blocking on I/O until time 79491ms [Q A1 A6 A3]
time 79477ms: Process A1 started using the CPU for 940ms burst [Q A6 A3]
time 79491ms: Process A0 completed I/O; added to ready queue [Q A6 A3 A0]
time 80417ms: Process A1 completed a CPU burst; 21 bursts to go [Q A6 A3 A0]
time 80417ms: Process A1 switching out of CPU; blocking on I/O until time 80865ms [Q A6 A3 A0]
time 80423ms: Process A6 started using the CPU for 556ms burst [Q A3 A0]
time 80865ms: Process A1 completed I/O; added to ready queue [Q A3 A0 A1]
time 80979ms: Process A6 completed a CPU burst; 19 bursts to go [Q A3 A0 A1]
time 80979ms: Process A6 switching out of CPU; blocking on I/O until time 84358ms [Q A3 A0 A1]
time 80985ms: Process A3 started using the CPU for 1144ms burst [Q A0 A1]
time 81292ms: Process A7 completed I/O; added to ready queue [Q A0 A1 A7]
time 82129ms: Process A3 completed a CPU burst; 6 bursts to go [Q A0 A1 A7]
time 82129ms: Process A3 switching out of CPU; blocking on I/O until time 82282ms [Q A0 A1 A7]
time 82135ms: Process A0 started using the CPU for 104ms burst [Q A1 A7]
time 82239ms: Process A0 completed a CPU burst; 18 bursts to go [Q A1 A7]
time 82239ms: Process A0 switching out of CPU; blocking on I/O until time 82670ms [Q A1 A7]
time 82245ms: Process A1 started using the CPU for 660ms burst [Q A7]
time 82282ms: Process A3 completed I/O; added to ready queue [Q A7 A3]
time 82670ms: Process A0 completed I/O; added to ready queue [Q A7 A3 A0]
time 82905ms: Process A1 completed a CPU burst; 20 bursts to go [Q A7 A3 A0]
time 82905ms: Process A1 switching out of CPU; blocking on I/O until time 82936ms [Q A7 A3 A0]
time 82911ms: Process A7 started using the CPU for 961ms burst [Q A3 A0]
time 82936ms: Process A1 completed I/O; added to ready queue [Q A3 A0 A1]
time 83872ms: Process A7 completed a CPU burst; 13 bursts to go [Q A3 A0 A1]
time 83872ms: Process A7 switching out of CPU; blocking on I/O until time 87307ms [Q A3 A0 A1]
time 83878ms: Process A3 started using the CPU for 492ms burst [Q A0 A1]
time 84358ms: Process A6 completed I/O; added to ready queue [Q A0 A1 A6]
time 84370ms: Process A3 completed a CPU burst; 5 bursts to go [Q A0 A1 A6]
time 84370ms: Process A3 switching out of CPU; blocking on I/O until time 84741ms [Q A0 A1 A6]
time 84376ms: Process A0 started using the CPU for 3924ms burst [Q A1 A6]
time 84741ms: Process A3 completed I/O; added to ready queue [Q A1 A6 A3]
time 87307ms: Process A7 completed I/O; added to ready queue [Q A1 A6 A3 A7]
time 88300ms: Process A0 completed a CPU burst; 17 bursts to go [Q A1 A6 A3 A7]
time 88300ms: Process A0 switching out of CPU; blocking on I/O until time 88970ms [Q A1 A6 A3 A7]
time 88306ms: Process A1 started using the CPU for 2196ms burst [Q A6 A3 A7]
time 88970ms: Process A0 completed I/O; added to ready queue [Q A6 A3 A7 A0]
time 90502ms: Process A1 completed a CPU burst; 19 bursts to go [Q A6 A3 A7 A0]
time 90502ms: Process A1 switching out of CPU; blocking on I/O until time 91481ms [Q A6 A3 A7 A0]
time 90508ms: Process A6 started using the CPU for 599ms burst [Q A3 A7 A0]
time 91107ms: Process A6 completed a CPU burst; 18 bursts to go [Q A3 A7 A0]
time 91107ms: Process A6 switching out of CPU; blocking on I/O until time 91670ms [Q A3 A7 A0]
time 91113ms: Process A3 started using the CPU for 2704ms burst [Q A7 A0]
time 91481ms: Process A1 completed I/O; added to ready queue [Q A7 A0 A1]
time 91670ms: Process A6 completed I/O; added to ready queue [Q A7 A0 A1 A6]
time 93817ms: Process A3 completed a CPU burst; 4 bursts to go [Q A7 A0 A1 A6]
time 93817ms: Process A3 switching out of CPU; blocking on I/O until time 93996ms [Q A7 A0 A1 A6]
time 93823ms: Process A7 started using the CPU for 587ms burst [Q A0 A1 A6]
time 93996ms: Process A3 completed I/O; added to ready queue [Q A0 A1 A6 A3]
time 94410ms: Process A7 completed a CPU burst; 12 bursts to go [Q A0 A1 A6 A3]
time 94410ms: Process A7 switching out of CPU; blocking on I/O until time 95205ms [Q A0 A1 A6 A3]
time 94416ms: Process A0 started using the CPU for 3388ms burst [Q A1 A6 A3]
time 95205ms: Process A7 completed I/O; added to ready queue [Q A1 A6 A3 A7]
time 97804ms: Process A0 completed a CPU burst; 16 bursts to go [Q A1 A6 A3 A7]
time 97804ms: Process A0 switching out of CPU; blocking on I/O until time 97901ms [Q A1 A6 A3 A7]
time 97810ms: Process A1 started using the CPU for 36ms burst [Q A6 A3 A7]
time 97846ms: Process A1 completed a CPU burst; 18 bursts to go [Q A6 A3 A7]
time 97846ms: Process A1 switching out of CPU; blocking on I/O until time 98486ms [Q A6 A3 A7]
time 97852ms: Process A6 started using the CPU for 58ms burst [Q A3 A7]
time 97901ms: Process A0 completed I/O; added to ready queue [Q A3 A7 A0]
time 97910ms: Process A6 completed a CPU burst; 17 bursts to go [Q A3 A7 A0]
time 97910ms: Process A6 switching out of CPU; blocking on I/O until time 99969ms [Q A3 A7 A0]
time 97916ms: Process A3 started using the CPU for 316ms burst [Q A7 A0]
time 98232ms: Process A3 completed a CPU burst; 3 bursts to go [Q A7 A0]
time 98232ms: Process A3 switching out of CPU; blocking on I/O until time 98903ms [Q A7 A0]
time 98238ms: Process A7 started using the CPU for 33ms burst [Q A0]
time 98271ms: Process A7 completed a CPU burst; 11 bursts to go [Q A0]
time 98271ms: Process A7 switching out of CPU; blocking on I/O until time 100858ms [Q A0]
time 98277ms: Process A0 started using the CPU for 100ms burst [Q empty]
time 98377ms: Process A0 completed a CPU burst; 15 bursts to go [Q empty]
time 98377ms: Process A0 switching out of CPU; blocking on I/O until time 98867ms [Q empty]
time 98486ms: Process A1 completed I/O; added to ready queue [Q A1]
time 98489ms: Process A1 started using the CPU for 4060ms burst [Q empty]
time 98867ms: Process A0 completed I/O; added to ready queue [Q A0]
time 98903ms: Process A3 completed I/O; added to ready queue [Q A0 A3]
time 99969ms: Process A6 completed I/O; added to ready queue [Q A0 A3 A6]
time 100858ms: Process A7 completed I/O; added to ready queue [Q A0 A3 A6 A7]
time 102549ms: Process A1 completed a CPU burst; 17 bursts to go [Q A0 A3 A6 A7]
time 102549ms: Process A1 switching out of CPU; blocking on I/O until time 102642ms [Q A0 A3 A6 A7]
time 102555ms: Process A0 started using the CPU for 3868ms burst [Q A3 A6 A7]
time 102642ms: Process A1 completed I/O; added to ready queue [Q A3 A6 A7 A1]
time 106423ms: Process A0 completed a CPU burst; 14 bursts to go [Q A3 A6 A7 A1]
time 106423ms: Process A0 switching out of CPU; blocking on I/O until time 106538ms [Q A3 A6 A7 A1]
time 106429ms: Process A3 started using the CPU for 204ms burst [Q A6 A7 A1]
time 106538ms: Process A0 completed I/O; added to ready queue [Q A6 A7 A1 A0]
time 106633ms: Process A3 completed a CPU burst; 2 bursts to go [Q A6 A7 A1 A0]
time 106633ms: Process A3 switching out of CPU; blocking on I/O until time 106968ms [Q A6 A7 A1 A0]
time 106639ms: Process A6 started using the CPU for 455ms burst [Q A7 A1 A0]
time 106968ms: Process A3 completed I/O; added to ready queue [Q A7 A1 A0 A3]
time 107094ms: Process A6 completed a CPU burst; 16 bursts to go [Q A7 A1 A0 A3]
time 107094ms: Process A6 switching out of CPU; blocking on I/O until time 110209ms [Q A7 A1 A0 A3]
time 107100ms: Process A7 started using the CPU for 875ms burst [Q A1 A0 A3]
time 107975ms: Process A7 completed a CPU burst; 10 bursts to go [Q A1 A0 A3]
time 107975ms: Process A7 switching out of CPU; blocking on I/O until time 110330ms [Q A1 A0 A3]
time 107981ms: Process A1 started using the CPU for 3904ms burst [Q A0 A3]
time 110209ms: Process A6 completed I/O; added to ready queue [Q A0 A3 A6]
time 110330ms: Process A7 completed I/O; added to ready queue [Q A0 A3 A6 A7]
time 111885ms: Process A1 completed a CPU burst; 16 bursts to go [Q A0 A3 A6 A7]
time 111885ms: Process A1 switching out of CPU; blocking on I/O until time 112422ms [Q A0 A3 A6 A7]
time 111891ms: Process A0 started using the CPU for 1516ms burst [Q A3 A6 A7]
time 112422ms: Process A1 completed I/O; added to ready queue [Q A3 A6 A7 A1]
time 113407ms: Process A0 completed a CPU burst; 13 bursts to go [Q A3 A6 A7 A1]
time 113407ms: Process A0 switching out of CPU; blocking on I/O until time 113721ms [Q A3 A6 A7 A1]
time 113413ms: Process A3 started using the CPU for 2328ms burst [Q A6 A7 A1]
time 113721ms: Process A0 completed I/O; added to ready queue [Q A6 A7 A1 A0]
time 115741ms: Process A3 completed a CPU burst; 1 burst to go [Q A6 A7 A1 A0]
time 115741ms: Process A3 switching out of CPU; blocking on I/O until time 116640ms [Q A6 A7 A1 A0]
time 115747ms: Process A6 started using the CPU for 826ms burst [Q A7 A1 A0]
time 116573ms: Process A6 completed a CPU burst; 15 bursts to go [Q A7 A1 A0]
time 116573ms: Process A6 switching out of CPU; blocking on I/O until time 119216ms [Q A7 A1 A0]
time 116579ms: Process A7 started using the CPU for 53ms burst [Q A1 A0]
time 116632ms: Process A7 completed a CPU burst; 9 bursts to go [Q A1 A0]
time 116632ms: Process A7 switching out of CPU; blocking on I/O until time 116875ms [Q A1 A0]
time 116638ms: Process A1 started using the CPU for 1488ms burst [Q A0]
time 116640ms: Process A3 completed I/O; added to ready queue [Q A0 A3]
time 116875ms: Process A7 completed I/O; added to ready queue [Q A0 A3 A7]
time 118126ms: Process A1 completed a CPU burst; 15 bursts to go [Q A0 A3 A7]
time 118126ms: Process A1 switching out of CPU; blocking on I/O until time 118533ms [Q A0 A3 A7]
time 118132ms: Process A0 started using the CPU for 1260ms burst [Q A3 A7]
time 118533ms: Process A1 completed I/O; added to ready queue [Q A3 A7 A1]
time 119216ms: Process A6 completed I/O; added to ready queue [Q A3 A7 A1 A6]
time 119392ms: Process A0 completed a CPU burst; 12 bursts to go [Q A3 A7 A1 A6]
time 119392ms: Process A0 switching out of CPU; blocking on I/O until time 119808ms [Q A3 A7 A1 A6]
time 119398ms: Process A3 started using the CPU for 2760ms burst [Q A7 A1 A6]
time 119808ms: Process A0 completed I/O; added to ready queue [Q A7 A1 A6 A0]
time 122158ms: Process A3 terminated [Q A7 A1 A6 A0]
time 122164ms: Process A7 started using the CPU for 64ms burst [Q A1 A6 A0]
time 122228ms: Process A7 completed a CPU burst; 8 bursts to go [Q A1 A6 A0]
time 122228ms: Process A7 switching out of CPU; blocking on I/O until time 125727ms [Q A1 A6 A0]
time 122234ms: Process A1 started using the CPU for 1080ms burst [Q A6 A0]
time 123314ms: Process A1 completed a CPU burst; 14 bursts to go [Q A6 A0]
time 123314ms: Process A1 switching out of CPU; blocking on I/O until time 123368ms [Q A6 A0]
time 123320ms: Process A6 started using the CPU for 587ms burst [Q A0]
time 123368ms: Process A1 completed I/O; added to ready queue [Q A0 A1]
time 123907ms: Process A6 completed a CPU burst; 14 bursts to go [Q A0 A1]
time 123907ms: Process A6 switching out of CPU; blocking on I/O until time 125830ms [Q A0 A1]
time 123913ms: Process A0 started using the CPU for 728ms burst [Q A1]
time 124641ms: Process A0 completed a CPU burst; 11 bursts to go [Q A1]
time 124641ms: Process A0 switching out of CPU; blocking on I/O until time 125417ms [Q A1]
time 124647ms: Process A1 started using the CPU for 916ms burst [Q empty]
time 125417ms: Process A0 completed I/O; added to ready queue [Q A0]
time 125563ms: Process A1 completed a CPU burst; 13 bursts to go [Q A0]
time 125563ms: Process A1 switching out of CPU; blocking on I/O until time 125637ms [Q A0]
time 125569ms: Process A0 started using the CPU for 2568ms burst [Q empty]
time 125637ms: Process A1 completed I/O; added to ready queue [Q A1]
time 125727ms: Process A7 completed I/O; added to ready queue [Q A1 A7]
time 125830ms: Process A6 completed I/O; added to ready queue [Q A1 A7 A6]
time 128137ms: Process A0 completed a CPU burst; 10 bursts to go [Q A1 A7 A6]
time 128137ms: Process A0 switching out of CPU; blocking on I/O until time 128488ms [Q A1 A7 A6]
time 128143ms: Process A1 started using the CPU for 3724ms burst [Q A7 A6]
time 128488ms: Process A0 completed I/O; added to ready queue [Q A7 A6 A0]
time 131867ms: Process A1 completed a CPU burst; 12 bursts to go [Q A7 A6 A0]
time 131867ms: Process A1 switching out of CPU; blocking on I/O until time 131981ms [Q A7 A6 A0]
time 131873ms: Process A7 started using the CPU for 264ms burst [Q A6 A0]
time 131981ms: Process A1 completed I/O; added to ready queue [Q A6 A0 A1]
time 132137ms: Process A7 completed a CPU burst; 7 bursts to go [Q A6 A0 A1]
time 132137ms: Process A7 switching out of CPU; blocking on I/O until time 133188ms [Q A6 A0 A1]
time 132143ms: Process A6 started using the CPU for 292ms burst [Q A0 A1]
time 132435ms: Process A6 completed a CPU burst; 13 bursts to go [Q A0 A1]
time 132435ms: Process A6 switching out of CPU; blocking on I/O until time 136918ms [Q A0 A1]
time 132441ms: Process A0 started using the CPU for 1220ms burst [Q A1]
time 133188ms: Process A7 completed I/O; added to ready queue [Q A1 A7]
time 133661ms: Process A0 completed a CPU burst; 9 bursts to go [Q A1 A7]
time 133661ms: Process A0 switching out of CPU; blocking on I/O until time 134547ms [Q A1 A7]
time 133667ms: Process A1 started using the CPU for 1764ms burst [Q A7]
time 134547ms: Process A0 completed I/O; added to ready queue [Q A7 A0]
time 135431ms: Process A1 completed a CPU burst; 11 bursts to go [Q A7 A0]
time 135431ms: Process A1 switching out of CPU; blocking on I/O until time 135716ms [Q A7 A0]
time 135437ms: Process A7 started using the CPU for 228ms burst [Q A0]
time 135665ms: Process A7 completed a CPU burst; 6 bursts to go [Q A0]
time 135665ms: Process A7 switching out of CPU; blocking on I/O until time 137932ms [Q A0]
time 135671ms: Process A0 started using the CPU for 2296ms burst [Q empty]
time 135716ms: Process A1 completed I/O; added to ready queue [Q A1]
time 136918ms: Process A6 completed I/O; added to ready queue [Q A1 A6]
time 137932ms: Process A7 completed I/O; added to ready queue [Q A1 A6 A7]
time 137967ms: Process A0 completed a CPU burst; 8 bursts to go [Q A1 A6 A7]
time 137967ms: Process A0 switching out of CPU; blocking on I/O until time 138634ms [Q A1 A6 A7]
time 137973ms: Process A1 started using the CPU for 860ms burst [Q A6 A7]
time 138634ms: Process A0 completed I/O; added to ready queue [Q A6 A7 A0]
time 138833ms: Process A1 completed a CPU burst; 10 bursts to go [Q A6 A7 A0]
time 138833ms: Process A1 switching out of CPU; blocking on I/O until time 138935ms [Q A6 A7 A0]
time 138839ms: Process A6 started using the CPU for 572ms burst [Q A7 A0]
time 138935ms: Process A1 completed I/O; added to ready queue [Q A7 A0 A1]
time 139411ms: Process A6 completed a CPU burst; 12 bursts to go [Q A7 A0 A1]
time 139411ms: Process A6 switching out of CPU; blocking on I/O until time 139934ms [Q A7 A0 A1]
time 139417ms: Process A7 started using the CPU for 37ms burst [Q A0 A1]
time 139454ms: Process A7 completed a CPU burst; 5 bursts to go [Q A0 A1]
time 139454ms: Process A7 switching out of CPU; blocking on I/O until time 144953ms [Q A0 A1]
time 139460ms: Process A0 started using the CPU for 3268ms burst [Q A1]
time 139934ms: Process A6 completed I/O; added to ready queue [Q A1 A6]
time 142728ms: Process A0 completed a CPU burst; 7 bursts to go [Q A1 A6]
time 142728ms: Process A0 switching out of CPU; blocking on I/O until time 143654ms [Q A1 A6]
time 142734ms: Process A1 started using the CPU for 2700ms burst [Q A6]
time 143654ms: Process A0 completed I/O; added to ready queue [Q A6 A0]
time 144953ms: Process A7 completed I/O; added to ready queue [Q A6 A0 A7]
time 145434ms: Process A1 completed a CPU burst; 9 bursts to go [Q A6 A0 A7]
time 145434ms: Process A1 switching out of CPU; blocking on I/O until time 146204ms [Q A6 A0 A7]
time 145440ms: Process A6 started using the CPU for 494ms burst [Q A0 A7]
time 145934ms: Process A6 completed a CPU burst; 11 bursts to go [Q A0 A7]
time 145934ms: Process A6 switching out of CPU; blocking on I/O until time 153025ms [Q A0 A7]
time 145940ms: Process A0 started using the CPU for 3468ms burst [Q A7]
time 146204ms: Process A1 completed I/O; added to ready queue [Q A7 A1]
time 149408ms: Process A0 completed a CPU burst; 6 bursts to go [Q A7 A1]
time 149408ms: Process A0 switching out of CPU; blocking on I/O until time 149699ms [Q A7 A1]
time 149414ms: Process A7 started using the CPU for 364ms burst [Q A1]
time 149699ms: Process A0 completed I/O; added to ready queue [Q A1 A0]
time 149778ms: Process A7 completed a CPU burst; 4 bursts to go [Q A1 A0]
time 149778ms: Process A7 switching out of CPU; blocking on I/O until time 154093ms [Q A1 A0]
time 149784ms: Process A1 started using the CPU for 100ms burst [Q A0]
time 149884ms: Process A1 completed a CPU burst; 8 bursts to go [Q A0]
time 149884ms: Process A1 switching out of CPU; blocking on I/O until time 150473ms [Q A0]
time 149890ms: Process A0 started using the CPU for 2392ms burst [Q empty]
time 150473ms: Process A1 completed I/O; added to ready queue [Q A1]
time 152282ms: Process A0 completed a CPU burst; 5 bursts to go [Q A1]
time 152282ms: Process A0 switching out of CPU; blocking on I/O until time 152393ms [Q A1]
time 152288ms: Process A1 started using the CPU for 420ms burst [Q empty]
time 152393ms: Process A0 completed I/O; added to ready queue [Q A0]
time 152708ms: Process A1 completed a CPU burst; 7 bursts to go [Q A0]
time 152708ms: Process A1 switching out of CPU; blocking on I/O until time 153420ms [Q A0]
time 152714ms: Process A0 started using the CPU for 1976ms burst [Q empty]
time 153025ms: Process A6 completed I/O; added to ready queue [Q A6]
time 153420ms: Process A1 completed I/O; added to ready queue [Q A6 A1]
time 154093ms: Process A7 completed I/O; added to ready queue [Q A6 A1 A7]
time 154690ms: Process A0 completed a CPU burst; 4 bursts to go [Q A6 A1 A7]
time 154690ms: Process A0 switching out of CPU; blocking on I/O until time 155257ms [Q A6 A1 A7]
time 154696ms: Process A6 started using the CPU for 19ms burst [Q A1 A7]
time 154715ms: Process A6 completed a CPU burst; 10 bursts to go [Q A1 A7]
time 154715ms: Process A6 switching out of CPU; blocking on I/O until time 158934ms [Q A1 A7]
time 154721ms: Process A1 started using the CPU for 3504ms burst [Q A7]
time 155257ms: Process A0 completed I/O; added to ready queue [Q A7 A0]
time 158225ms: Process A1 completed a CPU burst; 6 bursts to go [Q A7 A0]
time 158225ms: Process A1 switching out of CPU; blocking on I/O until time 158899ms [Q A7 A0]
time 158231ms: Process A7 started using the CPU for 278ms burst [Q A0]
time 158509ms: Process A7 completed a CPU burst; 3 bursts to go [Q A0]
time 158509ms: Process A7 switching out of CPU; blocking on I/O until time 161024ms [Q A0]
time 158515ms: Process A0 started using the CPU for 312ms burst [Q empty]
time 158827ms: Process A0 completed a CPU burst; 3 bursts to go [Q empty]
time 158827ms: Process A0 switching out of CPU; blocking on I/O until time 159375ms [Q empty]
time 158899ms: Process A1 completed I/O; added to ready queue [Q A1]
time 158902ms: Process A1 started using the CPU for 3504ms burst [Q empty]
time 158934ms: Process A6 completed I/O; added to ready queue [Q A6]
time 159375ms: Process A0 completed I/O; added to ready queue [Q A6 A0]
time 161024ms: Process A7 completed I/O; added to ready queue [Q A6 A0 A7]
time 162406ms: Process A1 completed a CPU burst; 5 bursts to go [Q A6 A0 A7]
time 162406ms: Process A1 switching out of CPU; blocking on I/O until time 162743ms [Q A6 A0 A7]
time 162412ms: Process A6 started using the CPU for 355ms burst [Q A0 A7]
time 162743ms: Process A1 completed I/O; added to ready queue [Q A0 A7 A1]
time 162767ms: Process A6 completed a CPU burst; 9 bursts to go [Q A0 A7 A1]
time 162767ms: Process A6 switching out of CPU; blocking on I/O until time 165738ms [Q A0 A7 A1]
time 162773ms: Process A0 started using the CPU for 1440ms burst [Q A7 A1]
time 164213ms: Process A0 completed a CPU burst; 2 bursts to go [Q A7 A1]
time 164213ms: Process A0 switching out of CPU; blocking on I/O until time 164352ms [Q A7 A1]
time 164219ms: Process A7 started using the CPU for 23ms burst [Q A1]
time 164242ms: Process A7 completed a CPU burst; 2 bursts to go [Q A1]
time 164242ms: Process A7 switching out of CPU; blocking on I/O until time 172125ms [Q A1]
time 164248ms: Process A1 started using the CPU for 2352ms burst [Q empty]
time 164352ms: Process A0 completed I/O; added to ready queue [Q A0]
time 165738ms: Process A6 completed I/O; added to ready queue [Q A0 A6]
time 166600ms: Process A1 completed a CPU burst; 4 bursts to go [Q A0 A6]
time 166600ms: Process A1 switching out of CPU; blocking on I/O until time 166854ms [Q A0 A6]
time 166606ms: Process A0 started using the CPU for 3052ms burst [Q A6]
time 166854ms: Process A1 completed I/O; added to ready queue [Q A6 A1]
time 169658ms: Process A0 completed a CPU burst; 1 burst to go [Q A6 A1]
time 169658ms: Process A0 switching out of CPU; blocking on I/O until time 170219ms [Q A6 A1]
time 169664ms: Process A6 started using the CPU for 81ms burst [Q A1]
time 169745ms: Process A6 completed a CPU burst; 8 bursts to go [Q A1]
time 169745ms: Process A6 switching out of CPU; blocking on I/O until time 177188ms [Q A1]
time 169751ms: Process A1 started using the CPU for 2652ms burst [Q empty]
time 170219ms: Process A0 completed I/O; added to ready queue [Q A0]
time 172125ms: Process A7 completed I/O; added to ready queue [Q A0 A7]
time 172403ms: Process A1 completed a CPU burst; 3 bursts to go [Q A0 A7]
time 172403ms: Process A1 switching out of CPU; blocking on I/O until time 173174ms [Q A0 A7]
time 172409ms: Process A0 started using the CPU for 2044ms burst [Q A7]
time 173174ms: Process A1 completed I/O; added to ready queue [Q A7 A1]
time 174453ms: Process A0 terminated [Q A7 A1]
time 174459ms: Process A7 started using the CPU for 188ms burst [Q A1]
time 174647ms: Process A7 completed a CPU burst; 1 burst to go [Q A1]
time 174647ms: Process A7 switching out of CPU; blocking on I/O until time 178546ms [Q A1]
time 174653ms: Process A1 started using the CPU for 3812ms burst [Q empty]
time 177188ms: Process A6 completed I/O; added to ready queue [Q A6]
time 178465ms: Process A1 completed a CPU burst; 2 bursts to go [Q A6]
time 178465ms: Process A1 switching out of CPU; blocking on I/O until time 178995ms [Q A6]
time 178471ms: Process A6 started using the CPU for 25ms burst [Q empty]
time 178496ms: Process A6 completed a CPU burst; 7 bursts to go [Q empty]
time 178496ms: Process A6 switching out of CPU; blocking on I/O until time 179443ms [Q empty]
time 178546ms: Process A7 completed I/O; added to ready queue [Q A7]
time 178549ms: Process A7 started using the CPU for 214ms burst [Q empty]
time 178763ms: Process A7 terminated [Q empty]
time 178995ms: Process A1 completed I/O; added to ready queue [Q A1]
time 178998ms: Process A1 started using the CPU for 2288ms burst [Q empty]
time 179443ms: Process A6 completed I/O; added to ready queue [Q A6]
time 181286ms: Process A1 completed a CPU burst; 1 burst to go [Q A6]
time 181286ms: Process A1 switching out of CPU; blocking on I/O until time 181455ms [Q A6]
time 181292ms: Process A6 started using the CPU for 445ms burst [Q empty]
time 181455ms: Process A1 completed I/O; added to ready queue [Q A1]
time 181737ms: Process A6 completed a CPU burst; 6 bursts to go [Q A1]
time 181737ms: Process A6 switching out of CPU; blocking on I/O until time 184948ms [Q A1]
time 181743ms: Process A1 started using the CPU for 388ms burst [Q empty]
time 182131ms: Process A1 terminated [Q empty]
time 184948ms: Process A6 completed I/O; added to ready queue [Q A6]
time 184951ms: Process A6 started using the CPU for 35ms burst [Q empty]
time 184986ms: Process A6 completed a CPU burst; 5 bursts to go [Q empty]
time 184986ms: Process A6 switching out of CPU; blocking on I/O until time 188029ms [Q empty]
time 188029ms: Process A6 completed I/O; added to ready queue [Q A6]
time 188032ms: Process A6 started using the CPU for 245ms burst [Q empty]
time 188277ms: Process A6 completed a CPU burst; 4 bursts to go [Q empty]
time 188277ms: Process A6 switching out of CPU; blocking on I/O until time 195520ms [Q empty]
time 195520ms: Process A6 completed I/O; added to ready queue [Q A6]
time 195523ms: Process A6 started using the CPU for 732ms burst [Q empty]
time 196255ms: Process A6 completed a CPU burst; 3 bursts to go [Q empty]
time 196255ms: Process A6 switching out of CPU; blocking on I/O until time 198322ms [Q empty]
time 198322ms: Process A6 completed I/O; added to ready queue [Q A6]
time 198325ms: Process A6 started using the CPU for 850ms burst [Q empty]
time 199175ms: Process A6 completed a CPU burst; 2 bursts to go [Q empty]
time 199175ms: Process A6 switching out of CPU; blocking on I/O until time 205978ms [Q empty]
time 205978ms: Process A6 completed I/O; added to ready queue [Q A6]
time 205981ms: Process A6 started using the CPU for 667ms burst [Q empty]
time 206648ms: Process A6 completed a CPU burst; 1 burst to go [Q empty]
time 206648ms: Process A6 switching out of CPU; blocking on I/O until time 206899ms [Q empty]
time 206899ms: Process A6 completed I/O; added to ready queue [Q A6]
time 206902ms: Process A6 started using the CPU for 370ms burst [Q empty]
time 207272ms: Process A6 terminated [Q empty]
time 207275ms: Simulator ended for FCFS [Q empty]

time 0ms: Simulator started for SJF [Q empty]
time 54ms: Process A0 (tau 1000ms) arrived; added to ready queue [Q A0]
time 56ms: Process A1 (tau 1000ms) arrived; added to ready queue [Q A1]
time 57ms: Process A0 (tau 1000ms) started using the CPU for 3764ms burst [Q A1]
time 115ms: Process A5 (tau 1000ms) arrived; added to ready queue [Q A1 A5]
time 242ms: Process A6 (tau 1000ms) arrived; added to ready queue [Q A1 A5 A6]
time 346ms: Process A4 (tau 1000ms) arrived; added to ready queue [Q A1 A5 A4 A6]
time 357ms: Process A7 (tau 1000ms) arrived; added to ready queue [Q A1 A5 A4 A7 A6]
time 456ms: Process A2 (tau 1000ms) arrived; added to ready queue [Q A1 A5 A4 A2 A7 A6]
time 758ms: Process A3 (tau 1000ms) arrived; added to ready queue [Q A1 A5 A4 A3 A2 A7 A6]
time 3821ms: Process A0 (tau 1000ms) completed a CPU burst; 28 bursts to go [Q A1 A5 A4 A3 A2 A7 A6]
time 3821ms: Recalculated tau for process A0: old tau 1000ms ==> new tau 3626ms [Q A1 A5 A4 A3 A2 A7 A6]
time 3821ms: Process A0 switching out of CPU; blocking on I/O until time 4510ms [Q A1 A5 A4 A3 A2 A7 A6]
time 3827ms: Process A1 (tau 1000ms) started using the CPU for 2828ms burst [Q A5 A4 A3 A2 A7 A6]
time 4510ms: Process A0 (tau 3626ms) completed I/O; added to ready queue [Q A5 A4 A3 A7 A2 A6 A0]
time 6655ms: Process A1 (tau 1000ms) completed a CPU burst; 30 bursts to go [Q A5 A4 A3 A7 A2 A6 A0]
time 6655ms: Recalculated tau for process A1: old tau 1000ms ==> new tau 2737ms [Q A5 A4 A3 A7 A2 A6 A0]
time 6655ms: Process A1 switching out of CPU; blocking on I/O until time 6980ms [Q A5 A4 A3 A7 A2 A6 A0]
time 6661ms: Process A5 (tau 1000ms) started using the CPU for 564ms burst [Q A4 A3 A7 A2 A6 A0]
time 6980ms: Process A1 (tau 2737ms) completed I/O; added to ready queue [Q A4 A3 A7 A2 A6 A1 A0]
time 7225ms: Process A5 terminated [Q A4 A3 A7 A2 A6 A1 A0]
time 7231ms: Process A4 (tau 1000ms) started using the CPU for 2428ms burst [Q A3 A7 A2 A6 A1 A0]
time 9659ms: Process A4 (tau 1000ms) completed a CPU burst; 1 burst to go [Q A3 A7 A2 A6 A1 A0]
time 9659ms: Recalculated tau for process A4: old tau 1000ms ==> new tau 2357ms [Q A3 A7 A2 A6 A1 A0]
time 9659ms: Process A4 switching out of CPU; blocking on I/O until time 10171ms [Q A3 A7 A2 A6 A1 A0]
time 9665ms: Process A3 (tau 1000ms) started using the CPU for 548ms burst [Q A7 A2 A6 A1 A0]
time 10171ms: Process A4 (tau 2357ms) completed I/O; added to ready queue [Q A7 A2 A6 A4 A1 A0]
time 10213ms: Process A3 (tau 1000ms) completed a CPU burst; 15 bursts to go [Q A7 A2 A6 A4 A1 A0]
time 10213ms: Recalculated tau for process A3: old tau 1000ms ==> new tau 571ms [Q A7 A2 A6 A4 A1 A0]
time 10213ms: Process A3 switching out of CPU; blocking on I/O until time 11015ms [Q A7 A2 A6 A4 A1 A0]
time 10219ms: Process A7 (tau 1000ms) started using the CPU for 297ms burst [Q A2 A6 A4 A1 A0]
time 10516ms: Process A7 (tau 1000ms) completed a CPU burst; 20 bursts to go [Q A2 A6 A4 A1 A0]
time 10516ms: Recalculated tau for process A7: old tau 1000ms ==> new tau 333ms [Q A2 A6 A4 A1 A0]
time 10516ms: Process A7 switching out of CPU; blocking on I/O until time 18383ms [Q A2 A6 A4 A1 A0]
time 10522ms: Process A2 (tau 1000ms) started using the CPU for 1896ms burst [Q A6 A4 A1 A0]
time 11015ms: Process A3 (tau 571ms) completed I/O; added to ready queue [Q A3 A6 A4 A1 A0]
time 12418ms: Process A2 (tau 1000ms) completed a CPU burst; 8 bursts to go [Q A3 A6 A4 A1 A0]
time 12418ms: Recalculated tau for process A2: old tau 1000ms ==> new tau 1852ms [Q A3 A6 A4 A1 A0]
time 12418ms: Process A2 switching out of CPU; blocking on I/O until time 13039ms [Q A3 A6 A4 A1 A0]
time 12424ms: Process A3 (tau 571ms) started using the CPU for 428ms burst [Q A6 A4 A1 A0]
time 12852ms: Process A3 (tau 571ms) completed a CPU burst; 14 bursts to go [Q A6 A4 A1 A0]
time 12852ms: Recalculated tau for process A3: old tau 571ms ==> new tau 436ms [Q A6 A4 A1 A0]
time 12852ms: Process A3 switching out of CPU; blocking on I/O until time 13793ms [Q A6 A4 A1 A0]
time 12858ms: Process A6 (tau 1000ms) started using the CPU for 761ms burst [Q A4 A1 A0]
time 13039ms: Process A2 (tau 1852ms) completed I/O; added to ready queue [Q A2 A4 A1 A0]
time 13619ms: Process A6 (tau 1000ms) completed a CPU burst; 26 bursts to go [Q A2 A4 A1 A0]
time 13619ms: Recalculated tau for process A6: old tau 1000ms ==> new tau 773ms [Q A2 A4 A1 A0]
time 13619ms: Process A6 switching out of CPU; blocking on I/O until time 15886ms [Q A2 A4 A1 A0]
time 13625ms: Process A2 (tau 1852ms) started using the CPU for 2940ms burst [Q A4 A1 A0]
time 13793ms: Process A3 (tau 436ms) completed I/O; added to ready queue [Q A3 A4 A1 A0]
time 15886ms: Process A6 (tau 773ms) completed I/O; added to ready queue [Q A3 A6 A4 A1 A0]
time 16565ms: Process A2 (tau 1852ms) completed a CPU burst; 7 bursts to go [Q A3 A6 A4 A1 A0]
time 16565ms: Recalculated tau for process A2: old tau 1852ms ==> new tau 2886ms [Q A3 A6 A4 A1 A0]
time 16565ms: Process A2 switching out of CPU; blocking on I/O until time 17007ms [Q A3 A6 A4 A1 A0]
time 16571ms: Process A3 (tau 436ms) started using the CPU for 1432ms burst [Q A6 A4 A1 A0]
time 17007ms: Process A2 (tau 2886ms) completed I/O; added to ready queue [Q A6 A4 A1 A2 A0]
time 18003ms: Process A3 (tau 436ms) completed a CPU burst; 13 bursts to go [Q A6 A4 A1 A2 A0]
time 18003ms: Recalculated tau for process A3: old tau 436ms ==> new tau 1383ms [Q A6 A4 A1 A2 A0]
time 18003ms: Process A3 switching out of CPU; blocking on I/O until time 18323ms [Q A6 A4 A1 A2 A0]
time 18009ms: Process A6 (tau 773ms) started using the CPU for 903ms burst [Q A4 A1 A2 A0]
time 18323ms: Process A3 (tau 1383ms) completed I/O; added to ready queue [Q A3 A4 A1 A2 A0]
time 18383ms: Process A7 (tau 333ms) completed I/O; added to ready queue [Q A7 A3 A4 A1 A2 A0]
time 18912ms: Process A6 (tau 773ms) completed a CPU burst; 25 bursts to go [Q A7 A3 A4 A1 A2 A0]
time 18912ms: Recalculated tau for process A6: old tau 773ms ==> new tau 897ms [Q A7 A3 A4 A1 A2 A0]
time 18912ms: Process A6 switching out of CPU; blocking on I/O until time 20963ms [Q A7 A3 A4 A1 A2 A0]
time 18918ms: Process A7 (tau 333ms) started using the CPU for 598ms burst [Q A3 A4 A1 A2 A0]
time 19516ms: Process A7 (tau 333ms) completed a CPU burst; 19 bursts to go [Q A3 A4 A1 A2 A0]
time 19516ms: Recalculated tau for process A7: old tau 333ms ==> new tau 585ms [Q A3 A4 A1 A2 A0]
time 19516ms: Process A7 switching out of CPU; blocking on I/O until time 21975ms [Q A3 A4 A1 A2 A0]
time 19522ms: Process A3 (tau 1383ms) started using the CPU for 3896ms burst [Q A4 A1 A2 A0]
time 20963ms: Process A6 (tau 897ms) completed I/O; added to ready queue [Q A6 A4 A1 A2 A0]
time 21975ms: Process A7 (tau 585ms) completed I/O; added to ready queue [Q A7 A6 A4 A1 A2 A0]
time 23418ms: Process A3 (tau 1383ms) completed a CPU burst; 12 bursts to go [Q A7 A6 A4 A1 A2 A0]
time 23418ms: Recalculated tau for process A3: old tau 1383ms ==> new tau 3771ms [Q A7 A6 A4 A1 A2 A0]
time 23418ms: Process A3 switching out of CPU; blocking on I/O until time 23545ms [Q A7 A6 A4 A1 A2 A0]
time 23424ms: Process A7 (tau 585ms) started using the CPU for 721ms burst [Q A6 A4 A1 A2 A0]
time 23545ms: Process A3 (tau 3771ms) completed I/O; added to ready queue [Q A6 A4 A1 A2 A0 A3]
time 24145ms: Process A7 (tau 585ms) completed a CPU burst; 18 bursts to go [Q A6 A4 A1 A2 A0 A3]
time 24145ms: Recalculated tau for process A7: old tau 585ms ==> new tau 715ms [Q A6 A4 A1 A2 A0 A3]
time 24145ms: Process A7 switching out of CPU; blocking on I/O until time 26884ms [Q A6 A4 A1 A2 A0 A3]
time 24151ms: Process A6 (tau 897ms) started using the CPU for 303ms burst [Q A4 A1 A2 A0 A3]
time 24454ms: Process A6 (tau 897ms) completed a CPU burst; 24 bursts to go [Q A4 A1 A2 A0 A3]
time 24454ms: Recalculated tau for process A6: old tau 897ms ==> new tau 333ms [Q A4 A1 A2 A0 A3]
time 24454ms: Process A6 switching out of CPU; blocking on I/O until time 31785ms [Q A4 A1 A2 A0 A3]
time 24460ms: Process A4 (tau 2357ms) started using the CPU for 2532ms burst [Q A1 A2 A0 A3]
time 26884ms: Process A7 (tau 715ms) completed I/O; added to ready queue [Q A7 A1 A2 A0 A3]
time 26992ms: Process A4 terminated [Q A7 A1 A2 A0 A3]
time 26998ms: Process A7 (tau 715ms) started using the CPU for 641ms burst [Q A1 A2 A0 A3]
time 27639ms: Process A7 (tau 715ms) completed a CPU burst; 17 bursts to go [Q A1 A2 A0 A3]
time 27639ms: Recalculated tau for process A7: old tau 715ms ==> new tau 645ms [Q A1 A2 A0 A3]
time 27639ms: Process A7 switching out of CPU; blocking on I/O until time 29586ms [Q A1 A2 A0 A3]
time 27645ms: Process A1 (tau 2737ms) started using the CPU for 1444ms burst [Q A2 A0 A3]
time 29089ms: Process A1 (tau 2737ms) completed a CPU burst; 29 bursts to go [Q A2 A0 A3]
time 29089ms: Recalculated tau for process A1: old tau 2737ms ==> new tau 1509ms [Q A2 A0 A3]
time 29089ms: Process A1 switching out of CPU; blocking on I/O until time 29259ms [Q A2 A0 A3]
time 29095ms: Process A2 (tau 2886ms) started using the CPU for 248ms burst [Q A0 A3]
time 29259ms: Process A1 (tau 1509ms) completed I/O; added to ready queue [Q A1 A0 A3]
time 29343ms: Process A2 (tau 2886ms) completed a CPU burst; 6 bursts to go [Q A1 A0 A3]
time 29343ms: Recalculated tau for process A2: old tau 2886ms ==> new tau 380ms [Q A1 A0 A3]
time 29343ms: Process A2 switching out of CPU; blocking on I/O until time 29810ms [Q A1 A0 A3]
time 29349ms: Process A1 (tau 1509ms) started using the CPU for 2476ms burst [Q A0 A3]
time 29586ms: Process A7 (tau 645ms) completed I/O; added to ready queue [Q A7 A0 A3]
time 29810ms: Process A2 (tau 380ms) completed I/O; added to ready queue [Q A2 A7 A0 A3]
time 31785ms: Process A6 (tau 333ms) completed I/O; added to ready queue [Q A6 A2 A7 A0 A3]
time 31825ms: Process A1 (tau 1509ms) completed a CPU burst; 28 bursts to go [Q A6 A2 A7 A0 A3]
time 31825ms: Recalculated tau for process A1: old tau 1509ms ==> new tau 2428ms [Q A6 A2 A7 A0 A3]
time 31825ms: Process A1 switching out of CPU; blocking on I/O until time 32245ms [Q A6 A2 A7 A0 A3]
time 31831ms: Process A6 (tau 333ms) started using the CPU for 194ms burst [Q A2 A7 A0 A3]
time 32025ms: Process A6 (tau 333ms) completed a CPU burst; 23 bursts to go [Q A2 A7 A0 A3]
time 32025ms: Recalculated tau for process A6: old tau 333ms ==> new tau 201ms [Q A2 A7 A0 A3]
time 32025ms: Process A6 switching out of CPU; blocking on I/O until time 38924ms [Q A2 A7 A0 A3]
time 32031ms: Process A2 (tau 380ms) started using the CPU for 952ms burst [Q A7 A0 A3]
time 32245ms: Process A1 (tau 2428ms) completed I/O; added to ready queue [Q A7 A1 A0 A3]
time 32983ms: Process A2 (tau 380ms) completed a CPU burst; 5 bursts to go [Q A7 A1 A0 A3]
time 32983ms: Recalculated tau for process A2: old tau 380ms ==> new tau 924ms [Q A7 A1 A0 A3]
time 32983ms: Process A2 switching out of CPU; blocking on I/O until time 33760ms [Q A7 A1 A0 A3]
time 32989ms: Process A7 (tau 645ms) started using the CPU for 128ms burst [Q A1 A0 A3]
time 33117ms: Process A7 (tau 645ms) completed a CPU burst; 16 bursts to go [Q A1 A0 A3]
time 33117ms: Recalculated tau for process A7: old tau 645ms ==> new tau 154ms [Q A1 A0 A3]
time 33117ms: Process A7 switching out of CPU; blocking on I/O until time 39288ms [Q A1 A0 A3]
time 33123ms: Process A1 (tau 2428ms) started using the CPU for 2256ms burst [Q A0 A3]
time 33760ms: Process A2 (tau 924ms) completed I/O; added to ready queue [Q A2 A0 A3]
time 35379ms: Process A1 (tau 2428ms) completed a CPU burst; 27 bursts to go [Q A2 A0 A3]
time 35379ms: Recalculated tau for process A1: old tau 2428ms ==> new tau 2265ms [Q A2 A0 A3]
time 35379ms: Process A1 switching out of CPU; blocking on I/O until time 35672ms [Q A2 A0 A3]
time 35385ms: Process A2 (tau 924ms) started using the CPU for 1796ms burst [Q A0 A3]
time 35672ms: Process A1 (tau 2265ms) completed I/O; added to ready queue [Q A1 A0 A3]
time 37181ms: Process A2 (tau 924ms) completed a CPU burst; 4 bursts to go [Q A1 A0 A3]
time 37181ms: Recalculated tau for process A2: old tau 924ms ==> new tau 1753ms [Q A1 A0 A3]
time 37181ms: Process A2 switching out of CPU; blocking on I/O until time 37595ms [Q A1 A0 A3]
time 37187ms: Process A1 (tau 2265ms) started using the CPU for 1188ms burst [Q A0 A3]
time 37595ms: Process A2 (tau 1753ms) completed I/O; added to ready queue [Q A2 A0 A3]
time 38375ms: Process A1 (tau 2265ms) completed a CPU burst; 26 bursts to go [Q A2 A0 A3]
time 38375ms: Recalculated tau for process A1: old tau 2265ms ==> new tau 1242ms [Q A2 A0 A3]
time 38375ms: Process A1 switching out of CPU; blocking on I/O until time 39155ms [Q A2 A0 A3]
time 38381ms: Process A2 (tau 1753ms) started using the CPU for 2200ms burst [Q A0 A3]
time 38924ms: Process A6 (tau 201ms) completed I/O; added to ready queue [Q A6 A0 A3]
time 39155ms: Process A1 (tau 1242ms) completed I/O; added to ready queue [Q A6 A1 A0 A3]
time 39288ms: Process A7 (tau 154ms) completed I/O; added to ready queue [Q A7 A6 A1 A0 A3]
time 40581ms: Process A2 (tau 1753ms) completed a CPU burst; 3 bursts to go [Q A7 A6 A1 A0 A3]
time 40581ms: Recalculated tau for process A2: old tau 1753ms ==> new tau 2178ms [Q A7 A6 A1 A0 A3]
time 40581ms: Process A2 switching out of CPU; blocking on I/O until time 40599ms [Q A7 A6 A1 A0 A3]
time 40587ms: Process A7 (tau 154ms) started using the CPU for 277ms burst [Q A6 A1 A0 A3]
time 40599ms: Process A2 (tau 2178ms) completed I/O; added to ready queue [Q A6 A1 A2 A0 A3]
time 40864ms: Process A7 (tau 154ms) completed a CPU burst; 15 bursts to go [Q A6 A1 A2 A0 A3]
time 40864ms: Recalculated tau for process A7: old tau 154ms ==> new tau 271ms [Q A6 A1 A2 A0 A3]
time 40864ms: Process A7 switching out of CPU; blocking on I/O until time 41715ms [Q A6 A1 A2 A0 A3]
time 40870ms: Process A6 (tau 201ms) started using the CPU for 203ms burst [Q A1 A2 A0 A3]
time 41073ms: Process A6 (tau 201ms) completed a CPU burst; 22 bursts to go [Q A1 A2 A0 A3]
time 41073ms: Recalculated tau for process A6: old tau 201ms ==> new tau 203ms [Q A1 A2 A0 A3]
time 41073ms: Process A6 switching out of CPU; blocking on I/O until time 43876ms [Q A1 A2 A0 A3]
time 41079ms: Process A1 (tau 1242ms) started using the CPU for 2812ms burst [Q A2 A0 A3]
time 41715ms: Process A7 (tau 271ms) completed I/O; added to ready queue [Q A7 A2 A0 A3]
time 43876ms: Process A6 (tau 203ms) completed I/O; added to ready queue [Q A6 A7 A2 A0 A3]
time 43891ms: Process A1 (tau 1242ms) completed a CPU burst; 25 bursts to go [Q A6 A7 A2 A0 A3]
time 43891ms: Recalculated tau for process A1: old tau 1242ms ==> new tau 2734ms [Q A6 A7 A2 A0 A3]
time 43891ms: Process A1 switching out of CPU; blocking on I/O until time 44757ms [Q A6 A7 A2 A0 A3]
time 43897ms: Process A6 (tau 203ms) started using the CPU for 603ms burst [Q A7 A2 A0 A3]
time 44500ms: Process A6 (tau 203ms) completed a CPU burst; 21 bursts to go [Q A7 A2 A0 A3]
time 44500ms: Recalculated tau for process A6: old tau 203ms ==> new tau 583ms [Q A7 A2 A0 A3]
time 44500ms: Process A6 switching out of CPU; blocking on I/O until time 47567ms [Q A7 A2 A0 A3]
time 44506ms: Process A7 (tau 271ms) started using the CPU for 984ms burst [Q A2 A0 A3]
time 44757ms: Process A1 (tau 2734ms) completed I/O; added to ready queue [Q A2 A1 A0 A3]
time 45490ms: Process A7 (tau 271ms) completed a CPU burst; 14 bursts to go [Q A2 A1 A0 A3]
time 45490ms: Recalculated tau for process A7: old tau 271ms ==> new tau 949ms [Q A2 A1 A0 A3]
time 45490ms: Process A7 switching out of CPU; blocking on I/O until time 50701ms [Q A2 A1 A0 A3]
time 45496ms: Process A2 (tau 2178ms) started using the CPU for 1512ms burst [Q A1 A0 A3]
time 47008ms: Process A2 (tau 2178ms) completed a CPU burst; 2 bursts to go [Q A1 A0 A3]
time 47008ms: Recalculated tau for process A2: old tau 2178ms ==> new tau 1546ms [Q A1 A0 A3]
time 47008ms: Process A2 switching out of CPU; blocking on I/O until time 47798ms [Q A1 A0 A3]
time 47014ms: Process A1 (tau 2734ms) started using the CPU for 368ms burst [Q A0 A3]
time 47382ms: Process A1 (tau 2734ms) completed a CPU burst; 24 bursts to go [Q A0 A3]
time 47382ms: Recalculated tau for process A1: old tau 2734ms ==> new tau 487ms [Q A0 A3]
time 47382ms: Process A1 switching out of CPU; blocking on I/O until time 47558ms [Q A0 A3]
time 47388ms: Process A0 (tau 3626ms) started using the CPU for 1732ms burst [Q A3]
time 47558ms: Process A1 (tau 487ms) completed I/O; added to ready queue [Q A1 A3]
time 47567ms: Process A6 (tau 583ms) completed I/O; added to ready queue [Q A1 A6 A3]
time 47798ms: Process A2 (tau 1546ms) completed I/O; added to ready queue [Q A1 A6 A2 A3]
time 49120ms: Process A0 (tau 3626ms) completed a CPU burst; 27 bursts to go [Q A1 A6 A2 A3]
time 49120ms: Recalculated tau for process A0: old tau 3626ms ==> new tau 1827ms [Q A1 A6 A2 A3]
time 49120ms: Process A0 switching out of CPU; blocking on I/O until time 49335ms [Q A1 A6 A2 A3]
time 49126ms: Process A1 (tau 487ms) started using the CPU for 200ms burst [Q A6 A2 A3]
time 49326ms: Process A1 (tau 487ms) completed a CPU burst; 23 bursts to go [Q A6 A2 A3]
time 49326ms: Recalculated tau for process A1: old tau 487ms ==> new tau 215ms [Q A6 A2 A3]
time 49326ms: Process A1 switching out of CPU; blocking on I/O until time 49936ms [Q A6 A2 A3]
time 49332ms: Process A6 (tau 583ms) started using the CPU for 95ms burst [Q A2 A3]
time 49335ms: Process A0 (tau 1827ms) completed I/O; added to ready queue [Q A2 A0 A3]
time 49427ms: Process A6 (tau 583ms) completed a CPU burst; 20 bursts to go [Q A2 A0 A3]
time 49427ms: Recalculated tau for process A6: old tau 583ms ==> new tau 120ms [Q A2 A0 A3]
time 49427ms: Process A6 switching out of CPU; blocking on I/O until time 50486ms [Q A2 A0 A3]
time 49433ms: Process A2 (tau 1546ms) started using the CPU for 1764ms burst [Q A0 A3]
time 49936ms: Process A1 (tau 215ms) completed I/O; added to ready queue [Q A1 A0 A3]
time 50486ms: Process A6 (tau 120ms) completed I/O; added to ready queue [Q A6 A1 A0 A3]
time 50701ms: Process A7 (tau 949ms) completed I/O; added to ready queue [Q A6 A1 A7 A0 A3]
time 51197ms: Process A2 (tau 1546ms) completed a CPU burst; 1 burst to go [Q A6 A1 A7 A0 A3]
time 51197ms: Recalculated tau for process A2: old tau 1546ms ==> new tau 1754ms [Q A6 A1 A7 A0 A3]
time 51197ms: Process A2 switching out of CPU; blocking on I/O until time 51284ms [Q A6 A1 A7 A0 A3]
time 51203ms: Process A6 (tau 120ms) started using the CPU for 556ms burst [Q A1 A7 A0 A3]
time 51284ms: Process A2 (tau 1754ms) completed I/O; added to ready queue [Q A1 A7 A2 A0 A3]
time 51759ms: Process A6 (tau 120ms) completed a CPU burst; 19 bursts to go [Q A1 A7 A2 A0 A3]
time 51759ms: Recalculated tau for process A6: old tau 120ms ==> new tau 535ms [Q A1 A7 A2 A0 A3]
time 51759ms: Process A6 switching out of CPU; blocking on I/O until time 55138ms [Q A1 A7 A2 A0 A3]
time 51765ms: Process A1 (tau 215ms) started using the CPU for 1044ms burst [Q A7 A2 A0 A3]
time 52809ms: Process A1 (tau 215ms) completed a CPU burst; 22 bursts to go [Q A7 A2 A0 A3]
time 52809ms: Recalculated tau for process A1: old tau 215ms ==> new tau 1003ms [Q A7 A2 A0 A3]
time 52809ms: Process A1 switching out of CPU; blocking on I/O until time 53404ms [Q A7 A2 A0 A3]
time 52815ms: Process A7 (tau 949ms) started using the CPU for 961ms burst [Q A2 A0 A3]
time 53404ms: Process A1 (tau 1003ms) completed I/O; added to ready queue [Q A1 A2 A0 A3]
time 53776ms: Process A7 (tau 949ms) completed a CPU burst; 13 bursts to go [Q A1 A2 A0 A3]
time 53776ms: Recalculated tau for process A7: old tau 949ms ==> new tau 961ms [Q A1 A2 A0 A3]
time 53776ms: Process A7 switching out of CPU; blocking on I/O until time 57211ms [Q A1 A2 A0 A3]
time 53782ms: Process A1 (tau 1003ms) started using the CPU for 940ms burst [Q A2 A0 A3]
time 54722ms: Process A1 (tau 1003ms) completed a CPU burst; 21 bursts to go [Q A2 A0 A3]
time 54722ms: Recalculated tau for process A1: old tau 1003ms ==> new tau 944ms [Q A2 A0 A3]
time 54722ms: Process A1 switching out of CPU; blocking on I/O until time 55170ms [Q A2 A0 A3]
time 54728ms: Process A2 (tau 1754ms) started using the CPU for 1768ms burst [Q A0 A3]
time 55138ms: Process A6 (tau 535ms) completed I/O; added to ready queue [Q A6 A0 A3]
time 55170ms: Process A1 (tau 944ms) completed I/O; added to ready queue [Q A6 A1 A0 A3]
time 56496ms: Process A2 terminated [Q A6 A1 A0 A3]
time 56502ms: Process A6 (tau 535ms) started using the CPU for 599ms burst [Q A1 A0 A3]
time 57101ms: Process A6 (tau 535ms) completed a CPU burst; 18 bursts to go [Q A1 A0 A3]
time 57101ms: Recalculated tau for process A6: old tau 535ms ==> new tau 596ms [Q A1 A0 A3]
time 57101ms: Process A6 switching out of CPU; blocking on I/O until time 57664ms [Q A1 A0 A3]
time 57107ms: Process A1 (tau 944ms) started using the CPU for 660ms burst [Q A0 A3]
time 57211ms: Process A7 (tau 961ms) completed I/O; added to ready queue [Q A7 A0 A3]
time 57664ms: Process A6 (tau 596ms) completed I/O; added to ready queue [Q A6 A7 A0 A3]
time 57767ms: Process A1 (tau 944ms) completed a CPU burst; 20 bursts to go [Q A6 A7 A0 A3]
time 57767ms: Recalculated tau for process A1: old tau 944ms ==> new tau 675ms [Q A6 A7 A0 A3]
time 57767ms: Process A1 switching out of CPU; blocking on I/O until time 57798ms [Q A6 A7 A0 A3]
time 57773ms: Process A6 (tau 596ms) started using the CPU for 58ms burst [Q A7 A0 A3]
time 57798ms: Process A1 (tau 675ms) completed I/O; added to ready queue [Q A1 A7 A0 A3]
time 57831ms: Process A6 (tau 596ms) completed a CPU burst; 17 bursts to go [Q A1 A7 A0 A3]
time 57831ms: Recalculated tau for process A6: old tau 596ms ==> new tau 85ms [Q A1 A7 A0 A3]
time 57831ms: Process A6 switching out of CPU; blocking on I/O until time 59890ms [Q A1 A7 A0 A3]
time 57837ms: Process A1 (tau 675ms) started using the CPU for 2196ms burst [Q A7 A0 A3]
time 59890ms: Process A6 (tau 85ms) completed I/O; added to ready queue [Q A6 A7 A0 A3]
time 60033ms: Process A1 (tau 675ms) completed a CPU burst; 19 bursts to go [Q A6 A7 A0 A3]
time 60033ms: Recalculated tau for process A1: old tau 675ms ==> new tau 2120ms [Q A6 A7 A0 A3]
time 60033ms: Process A1 switching out of CPU; blocking on I/O until time 61012ms [Q A6 A7 A0 A3]
time 60039ms: Process A6 (tau 85ms) started using the CPU for 455ms burst [Q A7 A0 A3]
time 60494ms: Process A6 (tau 85ms) completed a CPU burst; 16 bursts to go [Q A7 A0 A3]
time 60494ms: Recalculated tau for process A6: old tau 85ms ==> new tau 437ms [Q A7 A0 A3]
time 60494ms: Process A6 switching out of CPU; blocking on I/O until time 63609ms [Q A7 A0 A3]
time 60500ms: Process A7 (tau 961ms) started using the CPU for 587ms burst [Q A0 A3]
time 61012ms: Process A1 (tau 2120ms) completed I/O; added to ready queue [Q A0 A1 A3]
time 61087ms: Process A7 (tau 961ms) completed a CPU burst; 12 bursts to go [Q A0 A1 A3]
time 61087ms: Recalculated tau for process A7: old tau 961ms ==> new tau 606ms [Q A0 A1 A3]
time 61087ms: Process A7 switching out of CPU; blocking on I/O until time 61882ms [Q A0 A1 A3]
time 61093ms: Process A0 (tau 1827ms) started using the CPU for 844ms burst [Q A1 A3]
time 61882ms: Process A7 (tau 606ms) completed I/O; added to ready queue [Q A7 A1 A3]
time 61937ms: Process A0 (tau 1827ms) completed a CPU burst; 26 bursts to go [Q A7 A1 A3]
time 61937ms: Recalculated tau for process A0: old tau 1827ms ==> new tau 894ms [Q A7 A1 A3]
time 61937ms: Process A0 switching out of CPU; blocking on I/O until time 62433ms [Q A7 A1 A3]
time 61943ms: Process A7 (tau 606ms) started using the CPU for 33ms burst [Q A1 A3]
time 61976ms: Process A7 (tau 606ms) completed a CPU burst; 11 bursts to go [Q A1 A3]
time 61976ms: Recalculated tau for process A7: old tau 606ms ==> new tau 62ms [Q A1 A3]
time 61976ms: Process A7 switching out of CPU; blocking on I/O until time 64563ms [Q A1 A3]
time 61982ms: Process A1 (tau 2120ms) started using the CPU for 36ms burst [Q A3]
time 62018ms: Process A1 (tau 2120ms) completed a CPU burst; 18 bursts to go [Q A3]
time 62018ms: Recalculated tau for process A1: old tau 2120ms ==> new tau 141ms [Q A3]
time 62018ms: Process A1 switching out of CPU; blocking on I/O until time 62658ms [Q A3]
time 62024ms: Process A3 (tau 3771ms) started using the CPU for 804ms burst [Q empty]
time 62433ms: Process A0 (tau 894ms) completed I/O; added to ready queue [Q A0]
time 62658ms: Process A1 (tau 141ms) completed I/O; added to ready queue [Q A1 A0]
time 62828ms: Process A3 (tau 3771ms) completed a CPU burst; 11 bursts to go [Q A1 A0]
time 62828ms: Recalculated tau for process A3: old tau 3771ms ==> new tau 953ms [Q A1 A0]
time 62828ms: Process A3 switching out of CPU; blocking on I/O until time 62896ms [Q A1 A0]
time 62834ms: Process A1 (tau 141ms) started using the CPU for 4060ms burst [Q A0]
time 62896ms: Process A3 (tau 953ms) completed I/O; added to ready queue [Q A0 A3]
time 63609ms: Process A6 (tau 437ms) completed I/O; added to ready queue [Q A6 A0 A3]
time 64563ms: Process A7 (tau 62ms) completed I/O; added to ready queue [Q A7 A6 A0 A3]
time 66894ms: Process A1 (tau 141ms) completed a CPU burst; 17 bursts to go [Q A7 A6 A0 A3]
time 66894ms: Recalculated tau for process A1: old tau 141ms ==> new tau 3865ms [Q A7 A6 A0 A3]
time 66894ms: Process A1 switching out of CPU; blocking on I/O until time 66987ms [Q A7 A6 A0 A3]
time 66900ms: Process A7 (tau 62ms) started using the CPU for 875ms burst [Q A6 A0 A3]
time 66987ms: Process A1 (tau 3865ms) completed I/O; added to ready queue [Q A6 A0 A3 A1]
time 67775ms: Process A7 (tau 62ms) completed a CPU burst; 10 bursts to go [Q A6 A0 A3 A1]
time 67775ms: Recalculated tau for process A7: old tau 62ms ==> new tau 835ms [Q A6 A0 A3 A1]
time 67775ms: Process A7 switching out of CPU; blocking on I/O until time 70130ms [Q A6 A0 A3 A1]
time 67781ms: Process A6 (tau 437ms) started using the CPU for 826ms burst [Q A0 A3 A1]
time 68607ms: Process A6 (tau 437ms) completed a CPU burst; 15 bursts to go [Q A0 A3 A1]
time 68607ms: Recalculated tau for process A6: old tau 437ms ==> new tau 807ms [Q A0 A3 A1]
time 68607ms: Process A6 switching out of CPU; blocking on I/O until time 71250ms [Q A0 A3 A1]
time 68613ms: Process A0 (tau 894ms) started using the CPU for 168ms burst [Q A3 A1]
time 68781ms: Process A0 (tau 894ms) completed a CPU burst; 25 bursts to go [Q A3 A1]
time 68781ms: Recalculated tau for process A0: old tau 894ms ==> new tau 205ms [Q A3 A1]
time 68781ms: Process A0 switching out of CPU; blocking on I/O until time 69156ms [Q A3 A1]
time 68787ms: Process A3 (tau 953ms) started using the CPU for 2564ms burst [Q A1]
time 69156ms: Process A0 (tau 205ms) completed I/O; added to ready queue [Q A0 A1]
time 70130ms: Process A7 (tau 835ms) completed I/O; added to ready queue [Q A0 A7 A1]
time 71250ms: Process A6 (tau 807ms) completed I/O; added to ready queue [Q A0 A6 A7 A1]
time 71351ms: Process A3 (tau 953ms) completed a CPU burst; 10 bursts to go [Q A0 A6 A7 A1]
time 71351ms: Recalculated tau for process A3: old tau 953ms ==> new tau 2484ms [Q A0 A6 A7 A1]
time 71351ms: Process A3 switching out of CPU; blocking on I/O until time 71734ms [Q A0 A6 A7 A1]
time 71357ms: Process A0 (tau 205ms) started using the CPU for 736ms burst [Q A6 A7 A1]
time 71734ms: Process A3 (tau 2484ms) completed I/O; added to ready queue [Q A6 A7 A3 A1]
time 72093ms: Process A0 (tau 205ms) completed a CPU burst; 24 bursts to go [Q A6 A7 A3 A1]
time 72093ms: Recalculated tau for process A0: old tau 205ms ==> new tau 710ms [Q A6 A7 A3 A1]
time 72093ms: Process A0 switching out of CPU; blocking on I/O until time 72237ms [Q A6 A7 A3 A1]
time 72099ms: Process A6 (tau 807ms) started using the CPU for 587ms burst [Q A7 A3 A1]
time 72237ms: Process A0 (tau 710ms) completed I/O; added to ready queue [Q A0 A7 A3 A1]
time 72686ms: Process A6 (tau 807ms) completed a CPU burst; 14 bursts to go [Q A0 A7 A3 A1]
time 72686ms: Recalculated tau for process A6: old tau 807ms ==> new tau 598ms [Q A0 A7 A3 A1]
time 72686ms: Process A6 switching out of CPU; blocking on I/O until time 74609ms [Q A0 A7 A3 A1]
time 72692ms: Process A0 (tau 710ms) started using the CPU for 1372ms burst [Q A7 A3 A1]
time 74064ms: Process A0 (tau 710ms) completed a CPU burst; 23 bursts to go [Q A7 A3 A1]
time 74064ms: Recalculated tau for process A0: old tau 710ms ==> new tau 1339ms [Q A7 A3 A1]
time 74064ms: Process A0 switching out of CPU; blocking on I/O until time 74621ms [Q A7 A3 A1]
time 74070ms: Process A7 (tau 835ms) started using the CPU for 53ms burst [Q A3 A1]
time 74123ms: Process A7 (tau 835ms) completed a CPU burst; 9 bursts to go [Q A3 A1]
time 74123ms: Recalculated tau for process A7: old tau 835ms ==> new tau 93ms [Q A3 A1]
time 74123ms: Process A7 switching out of CPU; blocking on I/O until time 74366ms [Q A3 A1]
time 74129ms: Process A3 (tau 2484ms) started using the CPU for 3416ms burst [Q A1]
time 74366ms: Process A7 (tau 93ms) completed I/O; added to ready queue [Q A7 A1]
time 74609ms: Process A6 (tau 598ms) completed I/O; added to ready queue [Q A7 A6 A1]
time 74621ms: Process A0 (tau 1339ms) completed I/O; added to ready queue [Q A7 A6 A0 A1]
time 77545ms: Process A3 (tau 2484ms) completed a CPU burst; 9 bursts to go [Q A7 A6 A0 A1]
time 77545ms: Recalculated tau for process A3: old tau 2484ms ==> new tau 3370ms [Q A7 A6 A0 A1]
time 77545ms: Process A3 switching out of CPU; blocking on I/O until time 78437ms [Q A7 A6 A0 A1]
time 77551ms: Process A7 (tau 93ms) started using the CPU for 64ms burst [Q A6 A0 A1]
time 77615ms: Process A7 (tau 93ms) completed a CPU burst; 8 bursts to go [Q A6 A0 A1]
time 77615ms: Recalculated tau for process A7: old tau 93ms ==> new tau 66ms [Q A6 A0 A1]
time 77615ms: Process A7 switching out of CPU; blocking on I/O until time 81114ms [Q A6 A0 A1]
time 77621ms: Process A6 (tau 598ms) started using the CPU for 292ms burst [Q A0 A1]
time 77913ms: Process A6 (tau 598ms) completed a CPU burst; 13 bursts to go [Q A0 A1]
time 77913ms: Recalculated tau for process A6: old tau 598ms ==> new tau 308ms [Q A0 A1]
time 77913ms: Process A6 switching out of CPU; blocking on I/O until time 82396ms [Q A0 A1]
time 77919ms: Process A0 (tau 1339ms) started using the CPU for 1808ms burst [Q A1]
time 78437ms: Process A3 (tau 3370ms) completed I/O; added to ready queue [Q A3 A1]
time 79727ms: Process A0 (tau 1339ms) completed a CPU burst; 22 bursts to go [Q A3 A1]
time 79727ms: Recalculated tau for process A0: old tau 1339ms ==> new tau 1785ms [Q A3 A1]
time 79727ms: Process A0 switching out of CPU; blocking on I/O until time 79879ms [Q A3 A1]
time 79733ms: Process A3 (tau 3370ms) started using the CPU for 3756ms burst [Q A1]
time 79879ms: Process A0 (tau 1785ms) completed I/O; added to ready queue [Q A0 A1]
time 81114ms: Process A7 (tau 66ms) completed I/O; added to ready queue [Q A7 A0 A1]
time 82396ms: Process A6 (tau 308ms) completed I/O; added to ready queue [Q A7 A6 A0 A1]
time 83489ms: Process A3 (tau 3370ms) completed a CPU burst; 8 bursts to go [Q A7 A6 A0 A1]
time 83489ms: Recalculated tau for process A3: old tau 3370ms ==> new tau 3737ms [Q A7 A6 A0 A1]
time 83489ms: Process A3 switching out of CPU; blocking on I/O until time 84143ms [Q A7 A6 A0 A1]
time 83495ms: Process A7 (tau 66ms) started using the CPU for 264ms burst [Q A6 A0 A1]
time 83759ms: Process A7 (tau 66ms) completed a CPU burst; 7 bursts to go [Q A6 A0 A1]
time 83759ms: Recalculated tau for process A7: old tau 66ms ==> new tau 255ms [Q A6 A0 A1]
time 83759ms: Process A7 switching out of CPU; blocking on I/O until time 84810ms [Q A6 A0 A1]
time 83765ms: Process A6 (tau 308ms) started using the CPU for 572ms burst [Q A0 A1]
time 84143ms: Process A3 (tau 3737ms) completed I/O; added to ready queue [Q A0 A3 A1]
time 84337ms: Process A6 (tau 308ms) completed a CPU burst; 12 bursts to go [Q A0 A3 A1]
time 84337ms: Recalculated tau for process A6: old tau 308ms ==> new tau 559ms [Q A0 A3 A1]
time 84337ms: Process A6 switching out of CPU; blocking on I/O until time 84860ms [Q A0 A3 A1]
time 84343ms: Process A0 (tau 1785ms) started using the CPU for 1808ms burst [Q A3 A1]
time 84810ms: Process A7 (tau 255ms) completed I/O; added to ready queue [Q A7 A3 A1]
time 84860ms: Process A6 (tau 559ms) completed I/O; added to ready queue [Q A7 A6 A3 A1]
time 86151ms: Process A0 (tau 1785ms) completed a CPU burst; 21 bursts to go [Q A7 A6 A3 A1]
time 86151ms: Recalculated tau for process A0: old tau 1785ms ==> new tau 1807ms [Q A7 A6 A3 A1]
time 86151ms: Process A0 switching out of CPU; blocking on I/O until time 86420ms [Q A7 A6 A3 A1]
time 86157ms: Process A7 (tau 255ms) started using the CPU for 228ms burst [Q A6 A3 A1]
time 86385ms: Process A7 (tau 255ms) completed a CPU burst; 6 bursts to go [Q A6 A3 A1]
time 86385ms: Recalculated tau for process A7: old tau 255ms ==> new tau 230ms [Q A6 A3 A1]
time 86385ms: Process A7 switching out of CPU; blocking on I/O until time 88652ms [Q A6 A3 A1]
time 86391ms: Process A6 (tau 559ms) started using the CPU for 494ms burst [Q A3 A1]
time 86420ms: Process A0 (tau 1807ms) completed I/O; added to ready queue [Q A0 A3 A1]
time 86885ms: Process A6 (tau 559ms) completed a CPU burst; 11 bursts to go [Q A0 A3 A1]
time 86885ms: Recalculated tau for process A6: old tau 559ms ==> new tau 498ms [Q A0 A3 A1]
time 86885ms: Process A6 switching out of CPU; blocking on I/O until time 93976ms [Q A0 A3 A1]
time 86891ms: Process A0 (tau 1807ms) started using the CPU for 848ms burst [Q A3 A1]
time 87739ms: Process A0 (tau 1807ms) completed a CPU burst; 20 bursts to go [Q A3 A1]
time 87739ms: Recalculated tau for process A0: old tau 1807ms ==> new tau 896ms [Q A3 A1]
time 87739ms: Process A0 switching out of CPU; blocking on I/O until time 87817ms [Q A3 A1]
time 87745ms: Process A3 (tau 3737ms) started using the CPU for 3864ms burst [Q A1]
time 87817ms: Process A0 (tau 896ms) completed I/O; added to ready queue [Q A0 A1]
time 88652ms: Process A7 (tau 230ms) completed I/O; added to ready queue [Q A7 A0 A1]
time 91609ms: Process A3 (tau 3737ms) completed a CPU burst; 7 bursts to go [Q A7 A0 A1]
time 91609ms: Recalculated tau for process A3: old tau 3737ms ==> new tau 3858ms [Q A7 A0 A1]
time 91609ms: Process A3 switching out of CPU; blocking on I/O until time 92035ms [Q A7 A0 A1]
time 91615ms: Process A7 (tau 230ms) started using the CPU for 37ms burst [Q A0 A1]
time 91652ms: Process A7 (tau 230ms) completed a CPU burst; 5 bursts to go [Q A0 A1]
time 91652ms: Recalculated tau for process A7: old tau 230ms ==> new tau 47ms [Q A0 A1]
time 91652ms: Process A7 switching out of CPU; blocking on I/O until time 97151ms [Q A0 A1]
time 91658ms: Process A0 (tau 896ms) started using the CPU for 3384ms burst [Q A1]
time 92035ms: Process A3 (tau 3858ms) completed I/O; added to ready queue [Q A3 A1]
time 93976ms: Process A6 (tau 498ms) completed I/O; added to ready queue [Q A6 A3 A1]
time 95042ms: Process A0 (tau 896ms) completed a CPU burst; 19 bursts to go [Q A6 A3 A1]
time 95042ms: Recalculated tau for process A0: old tau 896ms ==> new tau 3260ms [Q A6 A3 A1]
time 95042ms: Process A0 switching out of CPU; blocking on I/O until time 95062ms [Q A6 A3 A1]
time 95048ms: Process A6 (tau 498ms) started using the CPU for 19ms burst [Q A3 A1]
time 95062ms: Process A0 (tau 3260ms) completed I/O; added to ready queue [Q A0 A3 A1]
time 95067ms: Process A6 (tau 498ms) completed a CPU burst; 10 bursts to go [Q A0 A3 A1]
time 95067ms: Recalculated tau for process A6: old tau 498ms ==> new tau 43ms [Q A0 A3 A1]
time 95067ms: Process A6 switching out of CPU; blocking on I/O until time 99286ms [Q A0 A3 A1]
time 95073ms: Process A0 (tau 3260ms) started using the CPU for 104ms burst [Q A3 A1]
time 95177ms: Process A0 (tau 3260ms) completed a CPU burst; 18 bursts to go [Q A3 A1]
time 95177ms: Recalculated tau for process A0: old tau 3260ms ==> new tau 262ms [Q A3 A1]
time 95177ms: Process A0 switching out of CPU; blocking on I/O until time 95608ms [Q A3 A1]
time 95183ms: Process A3 (tau 3858ms) started using the CPU for 1144ms burst [Q A1]
time 95608ms: Process A0 (tau 262ms) completed I/O; added to ready queue [Q A0 A1]
time 96327ms: Process A3 (tau 3858ms) completed a CPU burst; 6 bursts to go [Q A0 A1]
time 96327ms: Recalculated tau for process A3: old tau 3858ms ==> new tau 1280ms [Q A0 A1]
time 96327ms: Process A3 switching out of CPU; blocking on I/O until time 96480ms [Q A0 A1]
time 96333ms: Process A0 (tau 262ms) started using the CPU for 3924ms burst [Q A1]
time 96480ms: Process A3 (tau 1280ms) completed I/O; added to ready queue [Q A3 A1]
time 97151ms: Process A7 (tau 47ms) completed I/O; added to ready queue [Q A7 A3 A1]
time 99286ms: Process A6 (tau 43ms) completed I/O; added to ready queue [Q A6 A7 A3 A1]
time 100257ms: Process A0 (tau 262ms) completed a CPU burst; 17 bursts to go [Q A6 A7 A3 A1]
time 100257ms: Recalculated tau for process A0: old tau 262ms ==> new tau 3741ms [Q A6 A7 A3 A1]
time 100257ms: Process A0 switching out of CPU; blocking on I/O until time 100927ms [Q A6 A7 A3 A1]
time 100263ms: Process A6 (tau 43ms) started using the CPU for 355ms burst [Q A7 A3 A1]
time 100618ms: Process A6 (tau 43ms) completed a CPU burst; 9 bursts to go [Q A7 A3 A1]
time 100618ms: Recalculated tau for process A6: old tau 43ms ==> new tau 340ms [Q A7 A3 A1]
time 100618ms: Process A6 switching out of CPU; blocking on I/O until time 103589ms [Q A7 A3 A1]
time 100624ms: Process A7 (tau 47ms) started using the CPU for 364ms burst [Q A3 A1]
time 100927ms: Process A0 (tau 3741ms) completed I/O; added to ready queue [Q A3 A0 A1]
time 100988ms: Process A7 (tau 47ms) completed a CPU burst; 4 bursts to go [Q A3 A0 A1]
time 100988ms: Recalculated tau for process A7: old tau 47ms ==> new tau 349ms [Q A3 A0 A1]
time 100988ms: Process A7 switching out of CPU; blocking on I/O until time 105303ms [Q A3 A0 A1]
time 100994ms: Process A3 (tau 1280ms) started using the CPU for 492ms burst [Q A0 A1]
time 101486ms: Process A3 (tau 1280ms) completed a CPU burst; 5 bursts to go [Q A0 A1]
time 101486ms: Recalculated tau for process A3: old tau 1280ms ==> new tau 532ms [Q A0 A1]
time 101486ms: Process A3 switching out of CPU; blocking on I/O until time 101857ms [Q A0 A1]
time 101492ms: Process A0 (tau 3741ms) started using the CPU for 3388ms burst [Q A1]
time 101857ms: Process A3 (tau 532ms) completed I/O; added to ready queue [Q A3 A1]
time 103589ms: Process A6 (tau 340ms) completed I/O; added to ready queue [Q A6 A3 A1]
time 104880ms: Process A0 (tau 3741ms) completed a CPU burst; 16 bursts to go [Q A6 A3 A1]
time 104880ms: Recalculated tau for process A0: old tau 3741ms ==> new tau 3406ms [Q A6 A3 A1]
time 104880ms: Process A0 switching out of CPU; blocking on I/O until time 104977ms [Q A6 A3 A1]
time 104886ms: Process A6 (tau 340ms) started using the CPU for 81ms burst [Q A3 A1]
time 104967ms: Process A6 (tau 340ms) completed a CPU burst; 8 bursts to go [Q A3 A1]
time 104967ms: Recalculated tau for process A6: old tau 340ms ==> new tau 94ms [Q A3 A1]
time 104967ms: Process A6 switching out of CPU; blocking on I/O until time 112410ms [Q A3 A1]
time 104973ms: Process A3 (tau 532ms) started using the CPU for 2704ms burst [Q A1]
time 104977ms: Process A0 (tau 3406ms) completed I/O; added to ready queue [Q A0 A1]
time 105303ms: Process A7 (tau 349ms) completed I/O; added to ready queue [Q A7 A0 A1]
time 107677ms: Process A3 (tau 532ms) completed a CPU burst; 4 bursts to go [Q A7 A0 A1]
time 107677ms: Recalculated tau for process A3: old tau 532ms ==> new tau 2596ms [Q A7 A0 A1]
time 107677ms: Process A3 switching out of CPU; blocking on I/O until time 107856ms [Q A7 A0 A1]
time 107683ms: Process A7 (tau 349ms) started using the CPU for 278ms burst [Q A0 A1]
time 107856ms: Process A3 (tau 2596ms) completed I/O; added to ready queue [Q A3 A0 A1]
time 107961ms: Process A7 (tau 349ms) completed a CPU burst; 3 bursts to go [Q A3 A0 A1]
time 107961ms: Recalculated tau for process A7: old tau 349ms ==> new tau 282ms [Q A3 A0 A1]
time 107961ms: Process A7 switching out of CPU; blocking on I/O until time 110476ms [Q A3 A0 A1]
time 107967ms: Process A3 (tau 2596ms) started using the CPU for 316ms burst [Q A0 A1]
time 108283ms: Process A3 (tau 2596ms) completed a CPU burst; 3 bursts to go [Q A0 A1]
time 108283ms: Recalculated tau for process A3: old tau 2596ms ==> new tau 431ms [Q A0 A1]
time 108283ms: Process A3 switching out of CPU; blocking on I/O until time 108954ms [Q A0 A1]
time 108289ms: Process A0 (tau 3406ms) started using the CPU for 100ms burst [Q A1]
time 108389ms: Process A0 (tau 3406ms) completed a CPU burst; 15 bursts to go [Q A1]
time 108389ms: Recalculated tau for process A0: old tau 3406ms ==> new tau 266ms [Q A1]
time 108389ms: Process A0 switching out of CPU; blocking on I/O until time 108879ms [Q A1]
time 108395ms: Process A1 (tau 3865ms) started using the CPU for 3904ms burst [Q empty]
time 108879ms: Process A0 (tau 266ms) completed I/O; added to ready queue [Q A0]
time 108954ms: Process A3 (tau 431ms) completed I/O; added to ready queue [Q A0 A3]
time 110476ms: Process A7 (tau 282ms) completed I/O; added to ready queue [Q A0 A7 A3]
time 112299ms: Process A1 (tau 3865ms) completed a CPU burst; 16 bursts to go [Q A0 A7 A3]
time 112299ms: Recalculated tau for process A1: old tau 3865ms ==> new tau 3903ms [Q A0 A7 A3]
time 112299ms: Process A1 switching out of CPU; blocking on I/O until time 112836ms [Q A0 A7 A3]
time 112305ms: Process A0 (tau 266ms) started using the CPU for 3868ms burst [Q A7 A3]
time 112410ms: Process A6 (tau 94ms) completed I/O; added to ready queue [Q A6 A7 A3]
time 112836ms: Process A1 (tau 3903ms) completed I/O; added to ready queue [Q A6 A7 A3 A1]
time 116173ms: Process A0 (tau 266ms) completed a CPU burst; 14 bursts to go [Q A6 A7 A3 A1]
time 116173ms: Recalculated tau for process A0: old tau 266ms ==> new tau 3688ms [Q A6 A7 A3 A1]
time 116173ms: Process A0 switching out of CPU; blocking on I/O until time 116288ms [Q A6 A7 A3 A1]
time 116179ms: Process A6 (tau 94ms) started using the CPU for 25ms burst [Q A7 A3 A1]
time 116204ms: Process A6 (tau 94ms) completed a CPU burst; 7 bursts to go [Q A7 A3 A1]
time 116204ms: Recalculated tau for process A6: old tau 94ms ==> new tau 29ms [Q A7 A3 A1]
time 116204ms: Process A6 switching out of CPU; blocking on I/O until time 117151ms [Q A7 A3 A1]
time 116210ms: Process A7 (tau 282ms) started using the CPU for 23ms burst [Q A3 A1]
time 116233ms: Process A7 (tau 282ms) completed a CPU burst; 2 bursts to go [Q A3 A1]
time 116233ms: Recalculated tau for process A7: old tau 282ms ==> new tau 36ms [Q A3 A1]
time 116233ms: Process A7 switching out of CPU; blocking on I/O until time 124116ms [Q A3 A1]
time 116239ms: Process A3 (tau 431ms) started using the CPU for 204ms burst [Q A1]
time 116288ms: Process A0 (tau 3688ms) completed I/O; added to ready queue [Q A0 A1]
time 116443ms: Process A3 (tau 431ms) completed a CPU burst; 2 bursts to go [Q A0 A1]
time 116443ms: Recalculated tau for process A3: old tau 431ms ==> new tau 216ms [Q A0 A1]
time 116443ms: Process A3 switching out of CPU; blocking on I/O until time 116778ms [Q A0 A1]
time 116449ms: Process A0 (tau 3688ms) started using the CPU for 1516ms burst [Q A1]
time 116778ms: Process A3 (tau 216ms) completed I/O; added to ready queue [Q A3 A1]
time 117151ms: Process A6 (tau 29ms) completed I/O; added to ready queue [Q A6 A3 A1]
time 117965ms: Process A0 (tau 3688ms) completed a CPU burst; 13 bursts to go [Q A6 A3 A1]
time 117965ms: Recalculated tau for process A0: old tau 3688ms ==> new tau 1625ms [Q A6 A3 A1]
time 117965ms: Process A0 switching out of CPU; blocking on I/O until time 118279ms [Q A6 A3 A1]
time 117971ms: Process A6 (tau 29ms) started using the CPU for 445ms burst [Q A3 A1]
time 118279ms: Process A0 (tau 1625ms) completed I/O; added to ready queue [Q A3 A0 A1]
time 118416ms: Process A6 (tau 29ms) completed a CPU burst; 6 bursts to go [Q A3 A0 A1]
time 118416ms: Recalculated tau for process A6: old tau 29ms ==> new tau 425ms [Q A3 A0 A1]
time 118416ms: Process A6 switching out of CPU; blocking on I/O until time 121627ms [Q A3 A0 A1]
time 118422ms: Process A3 (tau 216ms) started using the CPU for 2328ms burst [Q A0 A1]
time 120750ms: Process A3 (tau 216ms) completed a CPU burst; 1 burst to go [Q A0 A1]
time 120750ms: Recalculated tau for process A3: old tau 216ms ==> new tau 2223ms [Q A0 A1]
time 120750ms: Process A3 switching out of CPU; blocking on I/O until time 121649ms [Q A0 A1]
time 120756ms: Process A0 (tau 1625ms) started using the CPU for 1260ms burst [Q A1]
time 121627ms: Process A6 (tau 425ms) completed I/O; added to ready queue [Q A6 A1]
time 121649ms: Process A3 (tau 2223ms) completed I/O; added to ready queue [Q A6 A3 A1]
time 122016ms: Process A0 (tau 1625ms) completed a CPU burst; 12 bursts to go [Q A6 A3 A1]
time 122016ms: Recalculated tau for process A0: old tau 1625ms ==> new tau 1279ms [Q A6 A3 A1]
time 122016ms: Process A0 switching out of CPU; blocking on I/O until time 122432ms [Q A6 A3 A1]
time 122022ms: Process A6 (tau 425ms) started using the CPU for 35ms burst [Q A3 A1]
time 122057ms: Process A6 (tau 425ms) completed a CPU burst; 5 bursts to go [Q A3 A1]
time 122057ms: Recalculated tau for process A6: old tau 425ms ==> new tau 55ms [Q A3 A1]
time 122057ms: Process A6 switching out of CPU; blocking on I/O until time 125100ms [Q A3 A1]
time 122063ms: Process A3 (tau 2223ms) started using the CPU for 2760ms burst [Q A1]
time 122432ms: Process A0 (tau 1279ms) completed I/O; added to ready queue [Q A0 A1]
time 124116ms: Process A7 (tau 36ms) completed I/O; added to ready queue [Q A7 A0 A1]
time 124823ms: Process A3 terminated [Q A7 A0 A1]
time 124829ms: Process A7 (tau 36ms) started using the CPU for 188ms burst [Q A0 A1]
time 125017ms: Process A7 (tau 36ms) completed a CPU burst; 1 burst to go [Q A0 A1]
time 125017ms: Recalculated tau for process A7: old tau 36ms ==> new tau 181ms [Q A0 A1]
time 125017ms: Process A7 switching out of CPU; blocking on I/O until time 128916ms [Q A0 A1]
time 125023ms: Process A0 (tau 1279ms) started using the CPU for 728ms burst [Q A1]
time 125100ms: Process A6 (tau 55ms) completed I/O; added to ready queue [Q A6 A1]
time 125751ms: Process A0 (tau 1279ms) completed a CPU burst; 11 bursts to go [Q A6 A1]
time 125751ms: Recalculated tau for process A0: old tau 1279ms ==> new tau 756ms [Q A6 A1]
time 125751ms: Process A0 switching out of CPU; blocking on I/O until time 126527ms [Q A6 A1]
time 125757ms: Process A6 (tau 55ms) started using the CPU for 245ms burst [Q A1]
time 126002ms: Process A6 (tau 55ms) completed a CPU burst; 4 bursts to go [Q A1]
time 126002ms: Recalculated tau for process A6: old tau 55ms ==> new tau 236ms [Q A1]
time 126002ms: Process A6 switching out of CPU; blocking on I/O until time 133245ms [Q A1]
time 126008ms: Process A1 (tau 3903ms) started using the CPU for 1488ms burst [Q empty]
time 126527ms: Process A0 (tau 756ms) completed I/O; added to ready queue [Q A0]
time 127496ms: Process A1 (tau 3903ms) completed a CPU burst; 15 bursts to go [Q A0]
time 127496ms: Recalculated tau for process A1: old tau 3903ms ==> new tau 1609ms [Q A0]
time 127496ms: Process A1 switching out of CPU; blocking on I/O until time 127903ms [Q A0]
time 127502ms: Process A0 (tau 756ms) started using the CPU for 2568ms burst [Q empty]
time 127903ms: Process A1 (tau 1609ms) completed I/O; added to ready queue [Q A1]
time 128916ms: Process A7 (tau 181ms) completed I/O; added to ready queue [Q A7 A1]
time 130070ms: Process A0 (tau 756ms) completed a CPU burst; 10 bursts to go [Q A7 A1]
time 130070ms: Recalculated tau for process A0: old tau 756ms ==> new tau 2478ms [Q A7 A1]
time 130070ms: Process A0 switching out of CPU; blocking on I/O until time 130421ms [Q A7 A1]
time 130076ms: Process A7 (tau 181ms) started using the CPU for 214ms burst [Q A1]
time 130290ms: Process A7 terminated [Q A1]
time 130296ms: Process A1 (tau 1609ms) started using the CPU for 1080ms burst [Q empty]
time 130421ms: Process A0 (tau 2478ms) completed I/O; added to ready queue [Q A0]
time 131376ms: Process A1 (tau 1609ms) completed a CPU burst; 14 bursts to go [Q A0]
time 131376ms: Recalculated tau for process A1: old tau 1609ms ==> new tau 1107ms [Q A0]
time 131376ms: Process A1 switching out of CPU; blocking on I/O until time 131430ms [Q A0]
time 131382ms: Process A0 (tau 2478ms) started using the CPU for 1220ms burst [Q empty]
time 131430ms: Process A1 (tau 1107ms) completed I/O; added to ready queue [Q A1]
time 132602ms: Process A0 (tau 2478ms) completed a CPU burst; 9 bursts to go [Q A1]
time 132602ms: Recalculated tau for process A0: old tau 2478ms ==> new tau 1283ms [Q A1]
time 132602ms: Process A0 switching out of CPU; blocking on I/O until time 133488ms [Q A1]
time 132608ms: Process A1 (tau 1107ms) started using the CPU for 916ms burst [Q empty]
time 133245ms: Process A6 (tau 236ms) completed I/O; added to ready queue [Q A6]
time 133488ms: Process A0 (tau 1283ms) completed I/O; added to ready queue [Q A6 A0]
time 133524ms: Process A1 (tau 1107ms) completed a CPU burst; 13 bursts to go [Q A6 A0]
time 133524ms: Recalculated tau for process A1: old tau 1107ms ==> new tau 926ms [Q A6 A0]
time 133524ms: Process A1 switching out of CPU; blocking on I/O until time 133598ms [Q A6 A0]
time 133530ms: Process A6 (tau 236ms) started using the CPU for 732ms burst [Q A0]
time 133598ms: Process A1 (tau 926ms) completed I/O; added to ready queue [Q A1 A0]
time 134262ms: Process A6 (tau 236ms) completed a CPU burst; 3 bursts to go [Q A1 A0]
time 134262ms: Recalculated tau for process A6: old tau 236ms ==> new tau 708ms [Q A1 A0]
time 134262ms: Process A6 switching out of CPU; blocking on I/O until time 136329ms [Q A1 A0]
time 134268ms: Process A1 (tau 926ms) started using the CPU for 3724ms burst [Q A0]
time 136329ms: Process A6 (tau 708ms) completed I/O; added to ready queue [Q A6 A0]
time 137992ms: Process A1 (tau 926ms) completed a CPU burst; 12 bursts to go [Q A6 A0]
time 137992ms: Recalculated tau for process A1: old tau 926ms ==> new tau 3585ms [Q A6 A0]
time 137992ms: Process A1 switching out of CPU; blocking on I/O until time 138106ms [Q A6 A0]
time 137998ms: Process A6 (tau 708ms) started using the CPU for 850ms burst [Q A0]
time 138106ms: Process A1 (tau 3585ms) completed I/O; added to ready queue [Q A0 A1]
time 138848ms: Process A6 (tau 708ms) completed a CPU burst; 2 bursts to go [Q A0 A1]
time 138848ms: Recalculated tau for process A6: old tau 708ms ==> new tau 843ms [Q A0 A1]
time 138848ms: Process A6 switching out of CPU; blocking on I/O until time 145651ms [Q A0 A1]
time 138854ms: Process A0 (tau 1283ms) started using the CPU for 2296ms burst [Q A1]
time 141150ms: Process A0 (tau 1283ms) completed a CPU burst; 8 bursts to go [Q A1]
time 141150ms: Recalculated tau for process A0: old tau 1283ms ==> new tau 2246ms [Q A1]
